Workbook
Name combo_4_4_data: [1]combo_4_4!$A$1:$A$13
Name combo_1_1_data: [2]combo_1_1!$A$1:$A$46
Name drop_005_003: [3]花名册隐藏下拉框!$I$1:$I$9
Name combo_14_14_data: [4]combo_14_14!$A$1:$A$277
Name combo_16_16_data: [4]combo_16_16!$A$1:$A$46
Name drop_004_013: [5]花名册隐藏下拉框!$G$1:$G$6

Sheet 4月考勤飞书发送版
A1: UserID | B1: 姓名 | C1: 月份 | D1: 区域 | E1: 部门 | F1: 转正时间 | G1: 应出勤天数 | H1: 实出勤天数 | I1: 迟到/早退时长(分钟） | J1: 缺卡次数 | K1: 旷工/天 | L1: 事假/天 | M1: 年假/天 | N1: 病假/天 | O1: 丧假/天 | P1: 婚假/天 | Q1: 产假/天 | R1: 调休/天 | S1: 加班/天 | T1: 法定节假日/天 | U1: 计薪天数 | V1: 乐捐/元 | W1: 补贴部分 | X1: 备注
W2: 全勤奖（元）
A3: 7494100833171013636 | B3: 熊文文 | C3: 4 | D3: 深圳 | E3: 财务部 | F3: 44552 | G3: =VLOOKUP($B3,INDIRECT($D3&"!$AG$1:$AY$66"),MATCH(G$1,INDIRECT($D3&"!$AG$1:$AY$1"),0),0) -> 24 | H3: =VLOOKUP($B3,INDIRECT($D3&"!$AG$1:$AY$66"),MATCH(H$1,INDIRECT($D3&"!$AG$1:$AY$1"),0),0) -> 22 | I3: =VLOOKUP($B3,INDIRECT($D3&"!$AG$1:$AY$66"),MATCH(I$1,INDIRECT($D3&"!$AG$1:$AY$1"),0),0) -> 0 | J3: =VLOOKUP($B3,INDIRECT($D3&"!$AG$1:$AY$66"),MATCH(J$1,INDIRECT($D3&"!$AG$1:$AY$1"),0),0) -> 0 | K3: =VLOOKUP($B3,INDIRECT($D3&"!$AG$1:$AY$66"),MATCH(K$1,INDIRECT($D3&"!$AG$1:$AY$1"),0),0) -> 0 | L3: =VLOOKUP($B3,INDIRECT($D3&"!$AG$1:$AY$66"),MATCH(L$1,INDIRECT($D3&"!$AG$1:$AY$1"),0),0) -> 0 | M3: =VLOOKUP($B3,INDIRECT($D3&"!$AG$1:$AY$66"),MATCH(M$1,INDIRECT($D3&"!$AG$1:$AY$1"),0),0) -> 1 | N3: =VLOOKUP($B3,INDIRECT($D3&"!$AG$1:$AY$66"),MATCH(N$1,INDIRECT($D3&"!$AG$1:$AY$1"),0),0) -> 0 | ... V3: =VLOOKUP($B3,INDIRECT($D3&"!$AG$1:$AY$66"),MATCH(V$1,INDIRECT($D3&"!$AG$1:$AY$1"),0),0) -> 0 | W3: =VLOOKUP($B3,INDIRECT($D3&"!$AG$1:$AY$66"),MATCH(W$2,INDIRECT($D3&"!$AG$1:$AY$1"),0),0) -> 200 | X3: =VLOOKUP($B3,INDIRECT($D3&"!$AG$1:$AZ$66"),MATCH(X$1,INDIRECT($D3&"!$AG$1:$AZ$1"),0),0) -> 全勤，年假 8小时(04/20 09:00-04/20 18:30)
A4: 7494458406943637507 | B4: 陈春叶 | C4: 4 | D4: 深圳 | E4: 财务部 | F4: 45727 | G4: =VLOOKUP($B4,INDIRECT($D4&"!$AG$1:$AY$66"),MATCH(G$1,INDIRECT($D4&"!$AG$1:$AY$1"),0),0) -> 24 | H4: =VLOOKUP($B4,INDIRECT($D4&"!$AG$1:$AY$66"),MATCH(H$1,INDIRECT($D4&"!$AG$1:$AY$1"),0),0) -> 22 | I4: =VLOOKUP($B4,INDIRECT($D4&"!$AG$1:$AY$66"),MATCH(I$1,INDIRECT($D4&"!$AG$1:$AY$1"),0),0) -> 0 | J4: =VLOOKUP($B4,INDIRECT($D4&"!$AG$1:$AY$66"),MATCH(J$1,INDIRECT($D4&"!$AG$1:$AY$1"),0),0) -> 0 | K4: =VLOOKUP($B4,INDIRECT($D4&"!$AG$1:$AY$66"),MATCH(K$1,INDIRECT($D4&"!$AG$1:$AY$1"),0),0) -> 0 | L4: =VLOOKUP($B4,INDIRECT($D4&"!$AG$1:$AY$66"),MATCH(L$1,INDIRECT($D4&"!$AG$1:$AY$1"),0),0) -> 0 | M4: =VLOOKUP($B4,INDIRECT($D4&"!$AG$1:$AY$66"),MATCH(M$1,INDIRECT($D4&"!$AG$1:$AY$1"),0),0) -> 1 | N4: =VLOOKUP($B4,INDIRECT($D4&"!$AG$1:$AY$66"),MATCH(N$1,INDIRECT($D4&"!$AG$1:$AY$1"),0),0) -> 0 | ... V4: =VLOOKUP($B4,INDIRECT($D4&"!$AG$1:$AY$66"),MATCH(V$1,INDIRECT($D4&"!$AG$1:$AY$1"),0),0) -> 0 | W4: =VLOOKUP($B4,INDIRECT($D4&"!$AG$1:$AY$66"),MATCH(W$2,INDIRECT($D4&"!$AG$1:$AY$1"),0),0) -> 200 | X4: =VLOOKUP($B4,INDIRECT($D4&"!$AG$1:$AY$66"),MATCH(X$1,INDIRECT($D4&"!$AG$1:$AY$1"),0),0) -> 全勤，外出 4.5小时(04/03 14:00-04/03 18:30);外出 6.5小时(04/22 12:00-04/22 18:30);年假 8小时(04/24 09:00-04/24 18:30)
A5: 7597988254654204880 | B5: 罗倩 | C5: 4 | D5: 深圳 | E5: 财务部 | F5: 46134 | G5: =VLOOKUP($B5,INDIRECT($D5&"!$AG$1:$AY$66"),MATCH(G$1,INDIRECT($D5&"!$AG$1:$AY$1"),0),0) -> 24 | H5: =VLOOKUP($B5,INDIRECT($D5&"!$AG$1:$AY$66"),MATCH(H$1,INDIRECT($D5&"!$AG$1:$AY$1"),0),0) -> 23 | I5: =VLOOKUP($B5,INDIRECT($D5&"!$AG$1:$AY$66"),MATCH(I$1,INDIRECT($D5&"!$AG$1:$AY$1"),0),0) -> 0 | J5: =VLOOKUP($B5,INDIRECT($D5&"!$AG$1:$AY$66"),MATCH(J$1,INDIRECT($D5&"!$AG$1:$AY$1"),0),0) -> 0 | K5: =VLOOKUP($B5,INDIRECT($D5&"!$AG$1:$AY$66"),MATCH(K$1,INDIRECT($D5&"!$AG$1:$AY$1"),0),0) -> 0 | L5: =VLOOKUP($B5,INDIRECT($D5&"!$AG$1:$AY$66"),MATCH(L$1,INDIRECT($D5&"!$AG$1:$AY$1"),0),0) -> 0 | M5: =VLOOKUP($B5,INDIRECT($D5&"!$AG$1:$AY$66"),MATCH(M$1,INDIRECT($D5&"!$AG$1:$AY$1"),0),0) -> 0 | N5: =VLOOKUP($B5,INDIRECT($D5&"!$AG$1:$AY$66"),MATCH(N$1,INDIRECT($D5&"!$AG$1:$AY$1"),0),0) -> 0 | ... V5: =VLOOKUP($B5,INDIRECT($D5&"!$AG$1:$AY$66"),MATCH(V$1,INDIRECT($D5&"!$AG$1:$AY$1"),0),0) -> 0 | W5: =VLOOKUP($B5,INDIRECT($D5&"!$AG$1:$AY$66"),MATCH(W$2,INDIRECT($D5&"!$AG$1:$AY$1"),0),0) -> 200 | X5: =VLOOKUP($B5,INDIRECT($D5&"!$AG$1:$AY$66"),MATCH(X$1,INDIRECT($D5&"!$AG$1:$AY$1"),0),0) -> 全勤，外出 1.5小时(04/28 10:30-04/28 12:00)
A6: 7617657975045442756 | B6: 李佳凤 | C6: 4 | D6: 深圳 | E6: 财务部 | G6: =VLOOKUP($B6,INDIRECT($D6&"!$AG$1:$AY$66"),MATCH(G$1,INDIRECT($D6&"!$AG$1:$AY$1"),0),0) -> 24 | H6: =VLOOKUP($B6,INDIRECT($D6&"!$AG$1:$AY$66"),MATCH(H$1,INDIRECT($D6&"!$AG$1:$AY$1"),0),0) -> 23 | I6: =VLOOKUP($B6,INDIRECT($D6&"!$AG$1:$AY$66"),MATCH(I$1,INDIRECT($D6&"!$AG$1:$AY$1"),0),0) -> 0 | J6: =VLOOKUP($B6,INDIRECT($D6&"!$AG$1:$AY$66"),MATCH(J$1,INDIRECT($D6&"!$AG$1:$AY$1"),0),0) -> 0 | K6: =VLOOKUP($B6,INDIRECT($D6&"!$AG$1:$AY$66"),MATCH(K$1,INDIRECT($D6&"!$AG$1:$AY$1"),0),0) -> 0 | L6: =VLOOKUP($B6,INDIRECT($D6&"!$AG$1:$AY$66"),MATCH(L$1,INDIRECT($D6&"!$AG$1:$AY$1"),0),0) -> 0 | M6: =VLOOKUP($B6,INDIRECT($D6&"!$AG$1:$AY$66"),MATCH(M$1,INDIRECT($D6&"!$AG$1:$AY$1"),0),0) -> 0 | N6: =VLOOKUP($B6,INDIRECT($D6&"!$AG$1:$AY$66"),MATCH(N$1,INDIRECT($D6&"!$AG$1:$AY$1"),0),0) -> 0 | ... V6: =VLOOKUP($B6,INDIRECT($D6&"!$AG$1:$AY$66"),MATCH(V$1,INDIRECT($D6&"!$AG$1:$AY$1"),0),0) -> 0 | W6: =VLOOKUP($B6,INDIRECT($D6&"!$AG$1:$AY$66"),MATCH(W$2,INDIRECT($D6&"!$AG$1:$AY$1"),0),0) -> 200 | X6: =VLOOKUP($B6,INDIRECT($D6&"!$AG$1:$AY$66"),MATCH(X$1,INDIRECT($D6&"!$AG$1:$AY$1"),0),0) -> 全勤
A7: 7560505191249018881 | B7: 李思思 | C7: 4 | D7: 深圳 | E7: 财务部 | F7: 46113 | G7: =VLOOKUP($B7,INDIRECT($D7&"!$AG$1:$AY$66"),MATCH(G$1,INDIRECT($D7&"!$AG$1:$AY$1"),0),0) -> 24 | H7: =VLOOKUP($B7,INDIRECT($D7&"!$AG$1:$AY$66"),MATCH(H$1,INDIRECT($D7&"!$AG$1:$AY$1"),0),0) -> 23 | I7: =VLOOKUP($B7,INDIRECT($D7&"!$AG$1:$AY$66"),MATCH(I$1,INDIRECT($D7&"!$AG$1:$AY$1"),0),0) -> 0 | J7: =VLOOKUP($B7,INDIRECT($D7&"!$AG$1:$AY$66"),MATCH(J$1,INDIRECT($D7&"!$AG$1:$AY$1"),0),0) -> 0 | K7: =VLOOKUP($B7,INDIRECT($D7&"!$AG$1:$AY$66"),MATCH(K$1,INDIRECT($D7&"!$AG$1:$AY$1"),0),0) -> 0 | L7: =VLOOKUP($B7,INDIRECT($D7&"!$AG$1:$AY$66"),MATCH(L$1,INDIRECT($D7&"!$AG$1:$AY$1"),0),0) -> 0 | M7: =VLOOKUP($B7,INDIRECT($D7&"!$AG$1:$AY$66"),MATCH(M$1,INDIRECT($D7&"!$AG$1:$AY$1"),0),0) -> 0 | N7: =VLOOKUP($B7,INDIRECT($D7&"!$AG$1:$AY$66"),MATCH(N$1,INDIRECT($D7&"!$AG$1:$AY$1"),0),0) -> 0 | ... V7: =VLOOKUP($B7,INDIRECT($D7&"!$AG$1:$AY$66"),MATCH(V$1,INDIRECT($D7&"!$AG$1:$AY$1"),0),0) -> 0 | W7: =VLOOKUP($B7,INDIRECT($D7&"!$AG$1:$AY$66"),MATCH(W$2,INDIRECT($D7&"!$AG$1:$AY$1"),0),0) -> 200 | X7: =VLOOKUP($B7,INDIRECT($D7&"!$AG$1:$AY$66"),MATCH(X$1,INDIRECT($D7&"!$AG$1:$AY$1"),0),0) -> 全勤，外出 6.5小时(04/22 12:00-04/22 18:30)
A8: 7494102874601947138 | B8: 邓茗霞 | C8: 4 | D8: 深圳 | E8: 采购部 | F8: 44732 | G8: =VLOOKUP($B8,INDIRECT($D8&"!$AG$1:$AY$66"),MATCH(G$1,INDIRECT($D8&"!$AG$1:$AY$1"),0),0) -> 24 | H8: =VLOOKUP($B8,INDIRECT($D8&"!$AG$1:$AY$66"),MATCH(H$1,INDIRECT($D8&"!$AG$1:$AY$1"),0),0) -> 22 | I8: =VLOOKUP($B8,INDIRECT($D8&"!$AG$1:$AY$66"),MATCH(I$1,INDIRECT($D8&"!$AG$1:$AY$1"),0),0) -> 5 | J8: =VLOOKUP($B8,INDIRECT($D8&"!$AG$1:$AY$66"),MATCH(J$1,INDIRECT($D8&"!$AG$1:$AY$1"),0),0) -> 0 | K8: =VLOOKUP($B8,INDIRECT($D8&"!$AG$1:$AY$66"),MATCH(K$1,INDIRECT($D8&"!$AG$1:$AY$1"),0),0) -> 0 | L8: =VLOOKUP($B8,INDIRECT($D8&"!$AG$1:$AY$66"),MATCH(L$1,INDIRECT($D8&"!$AG$1:$AY$1"),0),0) -> 0.44 | M8: =VLOOKUP($B8,INDIRECT($D8&"!$AG$1:$AY$66"),MATCH(M$1,INDIRECT($D8&"!$AG$1:$AY$1"),0),0) -> 0.56 | N8: =VLOOKUP($B8,INDIRECT($D8&"!$AG$1:$AY$66"),MATCH(N$1,INDIRECT($D8&"!$AG$1:$AY$1"),0),0) -> 0 | ... V8: =VLOOKUP($B8,INDIRECT($D8&"!$AG$1:$AY$66"),MATCH(V$1,INDIRECT($D8&"!$AG$1:$AY$1"),0),0) -> 0 | W8: =VLOOKUP($B8,INDIRECT($D8&"!$AG$1:$AY$66"),MATCH(W$2,INDIRECT($D8&"!$AG$1:$AY$1"),0),0) -> 0 | X8: =VLOOKUP($B8,INDIRECT($D8&"!$AG$1:$AY$66"),MATCH(X$1,INDIRECT($D8&"!$AG$1:$AY$1"),0),0) -> 事假 3.5小时(04/04 09:00-04/04 12:30);年假 4.5小时(04/10 14:00-04/10 18:30)，迟到2次共5分钟
A9: 7494105557268791297 | B9: 张丽玲 | C9: 4 | D9: 深圳 | E9: 采购部 | F9: 44739 | G9: =VLOOKUP($B9,INDIRECT($D9&"!$AG$1:$AY$66"),MATCH(G$1,INDIRECT($D9&"!$AG$1:$AY$1"),0),0) -> 24 | H9: =VLOOKUP($B9,INDIRECT($D9&"!$AG$1:$AY$66"),MATCH(H$1,INDIRECT($D9&"!$AG$1:$AY$1"),0),0) -> 22.44 | I9: =VLOOKUP($B9,INDIRECT($D9&"!$AG$1:$AY$66"),MATCH(I$1,INDIRECT($D9&"!$AG$1:$AY$1"),0),0) -> 0 | J9: =VLOOKUP($B9,INDIRECT($D9&"!$AG$1:$AY$66"),MATCH(J$1,INDIRECT($D9&"!$AG$1:$AY$1"),0),0) -> 0 | K9: =VLOOKUP($B9,INDIRECT($D9&"!$AG$1:$AY$66"),MATCH(K$1,INDIRECT($D9&"!$AG$1:$AY$1"),0),0) -> 0 | L9: =VLOOKUP($B9,INDIRECT($D9&"!$AG$1:$AY$66"),MATCH(L$1,INDIRECT($D9&"!$AG$1:$AY$1"),0),0) -> 0.56 | M9: =VLOOKUP($B9,INDIRECT($D9&"!$AG$1:$AY$66"),MATCH(M$1,INDIRECT($D9&"!$AG$1:$AY$1"),0),0) -> 0 | N9: =VLOOKUP($B9,INDIRECT($D9&"!$AG$1:$AY$66"),MATCH(N$1,INDIRECT($D9&"!$AG$1:$AY$1"),0),0) -> 0 | ... V9: =VLOOKUP($B9,INDIRECT($D9&"!$AG$1:$AY$66"),MATCH(V$1,INDIRECT($D9&"!$AG$1:$AY$1"),0),0) -> 0 | W9: =VLOOKUP($B9,INDIRECT($D9&"!$AG$1:$AY$66"),MATCH(W$2,INDIRECT($D9&"!$AG$1:$AY$1"),0),0) -> 0 | X9: =VLOOKUP($B9,INDIRECT($D9&"!$AG$1:$AY$66"),MATCH(X$1,INDIRECT($D9&"!$AG$1:$AY$1"),0),0) -> 事假 4.5小时(04/04 14:00-04/04 18:30)
A10: 7579801382065081549 | B10: 施晓珊 | C10: 4 | D10: 深圳 | E10: 采购部 | F10: 46085 | G10: =VLOOKUP($B10,INDIRECT($D10&"!$AG$1:$AY$66"),MATCH(G$1,INDIRECT($D10&"!$AG$1:$AY$1"),0),0) -> 24 | H10: =VLOOKUP($B10,INDIRECT($D10&"!$AG$1:$AY$66"),MATCH(H$1,INDIRECT($D10&"!$AG$1:$AY$1"),0),0) -> 23 | I10: =VLOOKUP($B10,INDIRECT($D10&"!$AG$1:$AY$66"),MATCH(I$1,INDIRECT($D10&"!$AG$1:$AY$1"),0),0) -> 0 | J10: =VLOOKUP($B10,INDIRECT($D10&"!$AG$1:$AY$66"),MATCH(J$1,INDIRECT($D10&"!$AG$1:$AY$1"),0),0) -> 0 | K10: =VLOOKUP($B10,INDIRECT($D10&"!$AG$1:$AY$66"),MATCH(K$1,INDIRECT($D10&"!$AG$1:$AY$1"),0),0) -> 0 | L10: =VLOOKUP($B10,INDIRECT($D10&"!$AG$1:$AY$66"),MATCH(L$1,INDIRECT($D10&"!$AG$1:$AY$1"),0),0) -> 0 | M10: =VLOOKUP($B10,INDIRECT($D10&"!$AG$1:$AY$66"),MATCH(M$1,INDIRECT($D10&"!$AG$1:$AY$1"),0),0) -> 0 | N10: =VLOOKUP($B10,INDIRECT($D10&"!$AG$1:$AY$66"),MATCH(N$1,INDIRECT($D10&"!$AG$1:$AY$1"),0),0) -> 0 | ... V10: =VLOOKUP($B10,INDIRECT($D10&"!$AG$1:$AY$66"),MATCH(V$1,INDIRECT($D10&"!$AG$1:$AY$1"),0),0) -> 0 | W10: =VLOOKUP($B10,INDIRECT($D10&"!$AG$1:$AY$66"),MATCH(W$2,INDIRECT($D10&"!$AG$1:$AY$1"),0),0) -> 200 | X10: =VLOOKUP($B10,INDIRECT($D10&"!$AG$1:$AY$66"),MATCH(X$1,INDIRECT($D10&"!$AG$1:$AY$1"),0),0) -> 全勤
A11: 7494101128265957380 | B11: 罗仁杰 | C11: 4 | D11: 深圳 | E11: 开发部 | F11: 45471 | G11: =VLOOKUP($B11,INDIRECT($D11&"!$AG$1:$AY$66"),MATCH(G$1,INDIRECT($D11&"!$AG$1:$AY$1"),0),0) -> 24 | H11: =VLOOKUP($B11,INDIRECT($D11&"!$AG$1:$AY$66"),MATCH(H$1,INDIRECT($D11&"!$AG$1:$AY$1"),0),0) -> 22 | I11: =VLOOKUP($B11,INDIRECT($D11&"!$AG$1:$AY$66"),MATCH(I$1,INDIRECT($D11&"!$AG$1:$AY$1"),0),0) -> 0 | J11: =VLOOKUP($B11,INDIRECT($D11&"!$AG$1:$AY$66"),MATCH(J$1,INDIRECT($D11&"!$AG$1:$AY$1"),0),0) -> 0 | K11: =VLOOKUP($B11,INDIRECT($D11&"!$AG$1:$AY$66"),MATCH(K$1,INDIRECT($D11&"!$AG$1:$AY$1"),0),0) -> 0 | L11: =VLOOKUP($B11,INDIRECT($D11&"!$AG$1:$AY$66"),MATCH(L$1,INDIRECT($D11&"!$AG$1:$AY$1"),0),0) -> 0 | M11: =VLOOKUP($B11,INDIRECT($D11&"!$AG$1:$AY$66"),MATCH(M$1,INDIRECT($D11&"!$AG$1:$AY$1"),0),0) -> 1 | N11: =VLOOKUP($B11,INDIRECT($D11&"!$AG$1:$AY$66"),MATCH(N$1,INDIRECT($D11&"!$AG$1:$AY$1"),0),0) -> 0 | ... V11: =VLOOKUP($B11,INDIRECT($D11&"!$AG$1:$AY$66"),MATCH(V$1,INDIRECT($D11&"!$AG$1:$AY$1"),0),0) -> 0 | W11: =VLOOKUP($B11,INDIRECT($D11&"!$AG$1:$AY$66"),MATCH(W$2,INDIRECT($D11&"!$AG$1:$AY$1"),0),0) -> 200 | X11: =VLOOKUP($B11,INDIRECT($D11&"!$AG$1:$AY$66"),MATCH(X$1,INDIRECT($D11&"!$AG$1:$AY$1"),0),0) -> 全勤，年假 8小时(04/24 09:00-04/24 18:30)
A12: 7494101393688068115 | B12: 彭永红 | C12: 4 | D12: 深圳 | E12: 开发部 | F12: 43360 | G12: =VLOOKUP($B12,INDIRECT($D12&"!$AG$1:$AY$66"),MATCH(G$1,INDIRECT($D12&"!$AG$1:$AY$1"),0),0) -> 24 | H12: =VLOOKUP($B12,INDIRECT($D12&"!$AG$1:$AY$66"),MATCH(H$1,INDIRECT($D12&"!$AG$1:$AY$1"),0),0) -> 23 | I12: =VLOOKUP($B12,INDIRECT($D12&"!$AG$1:$AY$66"),MATCH(I$1,INDIRECT($D12&"!$AG$1:$AY$1"),0),0) -> 0 | J12: =VLOOKUP($B12,INDIRECT($D12&"!$AG$1:$AY$66"),MATCH(J$1,INDIRECT($D12&"!$AG$1:$AY$1"),0),0) -> 0 | K12: =VLOOKUP($B12,INDIRECT($D12&"!$AG$1:$AY$66"),MATCH(K$1,INDIRECT($D12&"!$AG$1:$AY$1"),0),0) -> 0 | L12: =VLOOKUP($B12,INDIRECT($D12&"!$AG$1:$AY$66"),MATCH(L$1,INDIRECT($D12&"!$AG$1:$AY$1"),0),0) -> 0 | M12: =VLOOKUP($B12,INDIRECT($D12&"!$AG$1:$AY$66"),MATCH(M$1,INDIRECT($D12&"!$AG$1:$AY$1"),0),0) -> 0 | N12: =VLOOKUP($B12,INDIRECT($D12&"!$AG$1:$AY$66"),MATCH(N$1,INDIRECT($D12&"!$AG$1:$AY$1"),0),0) -> 0 | ... V12: =VLOOKUP($B12,INDIRECT($D12&"!$AG$1:$AY$66"),MATCH(V$1,INDIRECT($D12&"!$AG$1:$AY$1"),0),0) -> 0 | W12: =VLOOKUP($B12,INDIRECT($D12&"!$AG$1:$AY$66"),MATCH(W$2,INDIRECT($D12&"!$AG$1:$AY$1"),0),0) -> 200 | X12: =VLOOKUP($B12,INDIRECT($D12&"!$AG$1:$AY$66"),MATCH(X$1,INDIRECT($D12&"!$AG$1:$AY$1"),0),0) -> 全勤
A13: 7494101172369358852 | B13: 魏永伟 | C13: 4 | D13: 深圳 | E13: 开发部 | F13: 45468 | G13: =VLOOKUP($B13,INDIRECT($D13&"!$AG$1:$AY$66"),MATCH(G$1,INDIRECT($D13&"!$AG$1:$AY$1"),0),0) -> 24 | H13: =VLOOKUP($B13,INDIRECT($D13&"!$AG$1:$AY$66"),MATCH(H$1,INDIRECT($D13&"!$AG$1:$AY$1"),0),0) -> 23 | I13: =VLOOKUP($B13,INDIRECT($D13&"!$AG$1:$AY$66"),MATCH(I$1,INDIRECT($D13&"!$AG$1:$AY$1"),0),0) -> 0 | J13: =VLOOKUP($B13,INDIRECT($D13&"!$AG$1:$AY$66"),MATCH(J$1,INDIRECT($D13&"!$AG$1:$AY$1"),0),0) -> 0 | K13: =VLOOKUP($B13,INDIRECT($D13&"!$AG$1:$AY$66"),MATCH(K$1,INDIRECT($D13&"!$AG$1:$AY$1"),0),0) -> 0 | L13: =VLOOKUP($B13,INDIRECT($D13&"!$AG$1:$AY$66"),MATCH(L$1,INDIRECT($D13&"!$AG$1:$AY$1"),0),0) -> 0 | M13: =VLOOKUP($B13,INDIRECT($D13&"!$AG$1:$AY$66"),MATCH(M$1,INDIRECT($D13&"!$AG$1:$AY$1"),0),0) -> 0 | N13: =VLOOKUP($B13,INDIRECT($D13&"!$AG$1:$AY$66"),MATCH(N$1,INDIRECT($D13&"!$AG$1:$AY$1"),0),0) -> 0 | ... V13: =VLOOKUP($B13,INDIRECT($D13&"!$AG$1:$AY$66"),MATCH(V$1,INDIRECT($D13&"!$AG$1:$AY$1"),0),0) -> 0 | W13: =VLOOKUP($B13,INDIRECT($D13&"!$AG$1:$AY$66"),MATCH(W$2,INDIRECT($D13&"!$AG$1:$AY$1"),0),0) -> 200 | X13: =VLOOKUP($B13,INDIRECT($D13&"!$AG$1:$AY$66"),MATCH(X$1,INDIRECT($D13&"!$AG$1:$AY$1"),0),0) -> 全勤
A14: 7612460595211685045 | B14: 徐锡瑩 | C14: 4 | D14: 深圳 | E14: 开发部 | G14: =VLOOKUP($B14,INDIRECT($D14&"!$AG$1:$AY$66"),MATCH(G$1,INDIRECT($D14&"!$AG$1:$AY$1"),0),0) -> 24 | H14: =VLOOKUP($B14,INDIRECT($D14&"!$AG$1:$AY$66"),MATCH(H$1,INDIRECT($D14&"!$AG$1:$AY$1"),0),0) -> 23 | I14: =VLOOKUP($B14,INDIRECT($D14&"!$AG$1:$AY$66"),MATCH(I$1,INDIRECT($D14&"!$AG$1:$AY$1"),0),0) -> 1 | J14: =VLOOKUP($B14,INDIRECT($D14&"!$AG$1:$AY$66"),MATCH(J$1,INDIRECT($D14&"!$AG$1:$AY$1"),0),0) -> 0 | K14: =VLOOKUP($B14,INDIRECT($D14&"!$AG$1:$AY$66"),MATCH(K$1,INDIRECT($D14&"!$AG$1:$AY$1"),0),0) -> 0 | L14: =VLOOKUP($B14,INDIRECT($D14&"!$AG$1:$AY$66"),MATCH(L$1,INDIRECT($D14&"!$AG$1:$AY$1"),0),0) -> 0 | M14: =VLOOKUP($B14,INDIRECT($D14&"!$AG$1:$AY$66"),MATCH(M$1,INDIRECT($D14&"!$AG$1:$AY$1"),0),0) -> 0 | N14: =VLOOKUP($B14,INDIRECT($D14&"!$AG$1:$AY$66"),MATCH(N$1,INDIRECT($D14&"!$AG$1:$AY$1"),0),0) -> 0 | ... V14: =VLOOKUP($B14,INDIRECT($D14&"!$AG$1:$AY$66"),MATCH(V$1,INDIRECT($D14&"!$AG$1:$AY$1"),0),0) -> 0 | W14: =VLOOKUP($B14,INDIRECT($D14&"!$AG$1:$AY$66"),MATCH(W$2,INDIRECT($D14&"!$AG$1:$AY$1"),0),0) -> 0 | X14: =VLOOKUP($B14,INDIRECT($D14&"!$AG$1:$AY$66"),MATCH(X$1,INDIRECT($D14&"!$AG$1:$AY$1"),0),0) -> 迟到1分钟
A15: 7613565786199722939 | B15: 朱耀君 | C15: 4 | D15: 深圳 | E15: 开发部 | G15: =VLOOKUP($B15,INDIRECT($D15&"!$AG$1:$AY$66"),MATCH(G$1,INDIRECT($D15&"!$AG$1:$AY$1"),0),0) -> 24 | H15: =VLOOKUP($B15,INDIRECT($D15&"!$AG$1:$AY$66"),MATCH(H$1,INDIRECT($D15&"!$AG$1:$AY$1"),0),0) -> 23 | I15: =VLOOKUP($B15,INDIRECT($D15&"!$AG$1:$AY$66"),MATCH(I$1,INDIRECT($D15&"!$AG$1:$AY$1"),0),0) -> 0 | J15: =VLOOKUP($B15,INDIRECT($D15&"!$AG$1:$AY$66"),MATCH(J$1,INDIRECT($D15&"!$AG$1:$AY$1"),0),0) -> 0 | K15: =VLOOKUP($B15,INDIRECT($D15&"!$AG$1:$AY$66"),MATCH(K$1,INDIRECT($D15&"!$AG$1:$AY$1"),0),0) -> 0 | L15: =VLOOKUP($B15,INDIRECT($D15&"!$AG$1:$AY$66"),MATCH(L$1,INDIRECT($D15&"!$AG$1:$AY$1"),0),0) -> 0 | M15: =VLOOKUP($B15,INDIRECT($D15&"!$AG$1:$AY$66"),MATCH(M$1,INDIRECT($D15&"!$AG$1:$AY$1"),0),0) -> 0 | N15: =VLOOKUP($B15,INDIRECT($D15&"!$AG$1:$AY$66"),MATCH(N$1,INDIRECT($D15&"!$AG$1:$AY$1"),0),0) -> 0 | ... V15: =VLOOKUP($B15,INDIRECT($D15&"!$AG$1:$AY$66"),MATCH(V$1,INDIRECT($D15&"!$AG$1:$AY$1"),0),0) -> 0 | W15: =VLOOKUP($B15,INDIRECT($D15&"!$AG$1:$AY$66"),MATCH(W$2,INDIRECT($D15&"!$AG$1:$AY$1"),0),0) -> 200 | X15: =VLOOKUP($B15,INDIRECT($D15&"!$AG$1:$AY$66"),MATCH(X$1,INDIRECT($D15&"!$AG$1:$AY$1"),0),0) -> 全勤
A16: 7494100992892829715 | B16: 刘俊聪 | C16: 4 | D16: 深圳 | E16: 设计部 | F16: 43830 | G16: =VLOOKUP($B16,INDIRECT($D16&"!$AG$1:$AY$66"),MATCH(G$1,INDIRECT($D16&"!$AG$1:$AY$1"),0),0) -> 24 | H16: =VLOOKUP($B16,INDIRECT($D16&"!$AG$1:$AY$66"),MATCH(H$1,INDIRECT($D16&"!$AG$1:$AY$1"),0),0) -> 22 | I16: =VLOOKUP($B16,INDIRECT($D16&"!$AG$1:$AY$66"),MATCH(I$1,INDIRECT($D16&"!$AG$1:$AY$1"),0),0) -> 0 | J16: =VLOOKUP($B16,INDIRECT($D16&"!$AG$1:$AY$66"),MATCH(J$1,INDIRECT($D16&"!$AG$1:$AY$1"),0),0) -> 0 | K16: =VLOOKUP($B16,INDIRECT($D16&"!$AG$1:$AY$66"),MATCH(K$1,INDIRECT($D16&"!$AG$1:$AY$1"),0),0) -> 0 | L16: =VLOOKUP($B16,INDIRECT($D16&"!$AG$1:$AY$66"),MATCH(L$1,INDIRECT($D16&"!$AG$1:$AY$1"),0),0) -> 0 | M16: =VLOOKUP($B16,INDIRECT($D16&"!$AG$1:$AY$66"),MATCH(M$1,INDIRECT($D16&"!$AG$1:$AY$1"),0),0) -> 1 | N16: =VLOOKUP($B16,INDIRECT($D16&"!$AG$1:$AY$66"),MATCH(N$1,INDIRECT($D16&"!$AG$1:$AY$1"),0),0) -> 0 | ... V16: =VLOOKUP($B16,INDIRECT($D16&"!$AG$1:$AY$66"),MATCH(V$1,INDIRECT($D16&"!$AG$1:$AY$1"),0),0) -> 0 | W16: =VLOOKUP($B16,INDIRECT($D16&"!$AG$1:$AY$66"),MATCH(W$2,INDIRECT($D16&"!$AG$1:$AY$1"),0),0) -> 200 | X16: =VLOOKUP($B16,INDIRECT($D16&"!$AG$1:$AY$66"),MATCH(X$1,INDIRECT($D16&"!$AG$1:$AY$1"),0),0) -> 全勤，年假 8小时(04/01 09:00-04/01 18:30)
A17: 7494101078171467777 | B17: 吴竞涛 | C17: 4 | D17: 深圳 | E17: 设计部 | F17: 45546 | G17: =VLOOKUP($B17,INDIRECT($D17&"!$AG$1:$AY$66"),MATCH(G$1,INDIRECT($D17&"!$AG$1:$AY$1"),0),0) -> 24 | H17: =VLOOKUP($B17,INDIRECT($D17&"!$AG$1:$AY$66"),MATCH(H$1,INDIRECT($D17&"!$AG$1:$AY$1"),0),0) -> 13 | I17: =VLOOKUP($B17,INDIRECT($D17&"!$AG$1:$AY$66"),MATCH(I$1,INDIRECT($D17&"!$AG$1:$AY$1"),0),0) -> 0 | J17: =VLOOKUP($B17,INDIRECT($D17&"!$AG$1:$AY$66"),MATCH(J$1,INDIRECT($D17&"!$AG$1:$AY$1"),0),0) -> 0 | K17: =VLOOKUP($B17,INDIRECT($D17&"!$AG$1:$AY$66"),MATCH(K$1,INDIRECT($D17&"!$AG$1:$AY$1"),0),0) -> 0 | L17: =VLOOKUP($B17,INDIRECT($D17&"!$AG$1:$AY$66"),MATCH(L$1,INDIRECT($D17&"!$AG$1:$AY$1"),0),0) -> 1 | M17: =VLOOKUP($B17,INDIRECT($D17&"!$AG$1:$AY$66"),MATCH(M$1,INDIRECT($D17&"!$AG$1:$AY$1"),0),0) -> 0 | N17: =VLOOKUP($B17,INDIRECT($D17&"!$AG$1:$AY$66"),MATCH(N$1,INDIRECT($D17&"!$AG$1:$AY$1"),0),0) -> 0 | ... V17: =VLOOKUP($B17,INDIRECT($D17&"!$AG$1:$AY$66"),MATCH(V$1,INDIRECT($D17&"!$AG$1:$AY$1"),0),0) -> 0 | W17: =VLOOKUP($B17,INDIRECT($D17&"!$AG$1:$AY$66"),MATCH(W$2,INDIRECT($D17&"!$AG$1:$AY$1"),0),0) -> 0 | X17: =VLOOKUP($B17,INDIRECT($D17&"!$AG$1:$AY$66"),MATCH(X$1,INDIRECT($D17&"!$AG$1:$AY$1"),0),0) -> 事假 8小时(04/10 09:00-04/10 18:30),18日离职
A18: 7628041617374579672 | B18: 洪诗星 | C18: 4 | D18: 深圳 | E18: 设计部 | G18: =VLOOKUP($B18,INDIRECT($D18&"!$AG$1:$AY$66"),MATCH(G$1,INDIRECT($D18&"!$AG$1:$AY$1"),0),0) -> 24 | H18: =VLOOKUP($B18,INDIRECT($D18&"!$AG$1:$AY$66"),MATCH(H$1,INDIRECT($D18&"!$AG$1:$AY$1"),0),0) -> 15 | I18: =VLOOKUP($B18,INDIRECT($D18&"!$AG$1:$AY$66"),MATCH(I$1,INDIRECT($D18&"!$AG$1:$AY$1"),0),0) -> 0 | J18: =VLOOKUP($B18,INDIRECT($D18&"!$AG$1:$AY$66"),MATCH(J$1,INDIRECT($D18&"!$AG$1:$AY$1"),0),0) -> 0 | K18: =VLOOKUP($B18,INDIRECT($D18&"!$AG$1:$AY$66"),MATCH(K$1,INDIRECT($D18&"!$AG$1:$AY$1"),0),0) -> 0 | L18: =VLOOKUP($B18,INDIRECT($D18&"!$AG$1:$AY$66"),MATCH(L$1,INDIRECT($D18&"!$AG$1:$AY$1"),0),0) -> 0 | M18: =VLOOKUP($B18,INDIRECT($D18&"!$AG$1:$AY$66"),MATCH(M$1,INDIRECT($D18&"!$AG$1:$AY$1"),0),0) -> 0 | N18: =VLOOKUP($B18,INDIRECT($D18&"!$AG$1:$AY$66"),MATCH(N$1,INDIRECT($D18&"!$AG$1:$AY$1"),0),0) -> 0 | ... V18: =VLOOKUP($B18,INDIRECT($D18&"!$AG$1:$AY$66"),MATCH(V$1,INDIRECT($D18&"!$AG$1:$AY$1"),0),0) -> 0 | W18: =VLOOKUP($B18,INDIRECT($D18&"!$AG$1:$AY$66"),MATCH(W$2,INDIRECT($D18&"!$AG$1:$AY$1"),0),0) -> 0 | X18: =VLOOKUP($B18,INDIRECT($D18&"!$AG$1:$AY$66"),MATCH(X$1,INDIRECT($D18&"!$AG$1:$AY$1"),0),0) -> 13日入职
A19: 7494103173159010307 | B19: 刘士灵 | C19: 4 | D19: 深圳 | E19: 物流部 | F19: 43781 | G19: =VLOOKUP($B19,INDIRECT($D19&"!$AG$1:$AY$66"),MATCH(G$1,INDIRECT($D19&"!$AG$1:$AY$1"),0),0) -> 24 | H19: =VLOOKUP($B19,INDIRECT($D19&"!$AG$1:$AY$66"),MATCH(H$1,INDIRECT($D19&"!$AG$1:$AY$1"),0),0) -> 23 | I19: =VLOOKUP($B19,INDIRECT($D19&"!$AG$1:$AY$66"),MATCH(I$1,INDIRECT($D19&"!$AG$1:$AY$1"),0),0) -> 1 | J19: =VLOOKUP($B19,INDIRECT($D19&"!$AG$1:$AY$66"),MATCH(J$1,INDIRECT($D19&"!$AG$1:$AY$1"),0),0) -> 2 | K19: =VLOOKUP($B19,INDIRECT($D19&"!$AG$1:$AY$66"),MATCH(K$1,INDIRECT($D19&"!$AG$1:$AY$1"),0),0) -> 0 | L19: =VLOOKUP($B19,INDIRECT($D19&"!$AG$1:$AY$66"),MATCH(L$1,INDIRECT($D19&"!$AG$1:$AY$1"),0),0) -> 0 | M19: =VLOOKUP($B19,INDIRECT($D19&"!$AG$1:$AY$66"),MATCH(M$1,INDIRECT($D19&"!$AG$1:$AY$1"),0),0) -> 0 | N19: =VLOOKUP($B19,INDIRECT($D19&"!$AG$1:$AY$66"),MATCH(N$1,INDIRECT($D19&"!$AG$1:$AY$1"),0),0) -> 0 | ... V19: =VLOOKUP($B19,INDIRECT($D19&"!$AG$1:$AY$66"),MATCH(V$1,INDIRECT($D19&"!$AG$1:$AY$1"),0),0) -> 0 | W19: =VLOOKUP($B19,INDIRECT($D19&"!$AG$1:$AY$66"),MATCH(W$2,INDIRECT($D19&"!$AG$1:$AY$1"),0),0) -> 0 | X19: =VLOOKUP($B19,INDIRECT($D19&"!$AG$1:$AY$66"),MATCH(X$1,INDIRECT($D19&"!$AG$1:$AY$1"),0),0) -> 缺卡2次，迟到1分钟
A20: 7583885494455389385 | B20: 杨汇雯 | C20: 4 | D20: 深圳 | E20: 物流部 | F20: 46096 | G20: =VLOOKUP($B20,INDIRECT($D20&"!$AG$1:$AY$66"),MATCH(G$1,INDIRECT($D20&"!$AG$1:$AY$1"),0),0) -> 24 | H20: =VLOOKUP($B20,INDIRECT($D20&"!$AG$1:$AY$66"),MATCH(H$1,INDIRECT($D20&"!$AG$1:$AY$1"),0),0) -> 23 | I20: =VLOOKUP($B20,INDIRECT($D20&"!$AG$1:$AY$66"),MATCH(I$1,INDIRECT($D20&"!$AG$1:$AY$1"),0),0) -> 0 | J20: =VLOOKUP($B20,INDIRECT($D20&"!$AG$1:$AY$66"),MATCH(J$1,INDIRECT($D20&"!$AG$1:$AY$1"),0),0) -> 0 | K20: =VLOOKUP($B20,INDIRECT($D20&"!$AG$1:$AY$66"),MATCH(K$1,INDIRECT($D20&"!$AG$1:$AY$1"),0),0) -> 0 | L20: =VLOOKUP($B20,INDIRECT($D20&"!$AG$1:$AY$66"),MATCH(L$1,INDIRECT($D20&"!$AG$1:$AY$1"),0),0) -> 0 | M20: =VLOOKUP($B20,INDIRECT($D20&"!$AG$1:$AY$66"),MATCH(M$1,INDIRECT($D20&"!$AG$1:$AY$1"),0),0) -> 0 | N20: =VLOOKUP($B20,INDIRECT($D20&"!$AG$1:$AY$66"),MATCH(N$1,INDIRECT($D20&"!$AG$1:$AY$1"),0),0) -> 0 | ... V20: =VLOOKUP($B20,INDIRECT($D20&"!$AG$1:$AY$66"),MATCH(V$1,INDIRECT($D20&"!$AG$1:$AY$1"),0),0) -> 0 | W20: =VLOOKUP($B20,INDIRECT($D20&"!$AG$1:$AY$66"),MATCH(W$2,INDIRECT($D20&"!$AG$1:$AY$1"),0),0) -> 200 | X20: =VLOOKUP($B20,INDIRECT($D20&"!$AG$1:$AY$66"),MATCH(X$1,INDIRECT($D20&"!$AG$1:$AY$1"),0),0) -> 全勤
A21: 7501522421528133633 | B21: 史泰龙 | C21: 4 | D21: 深圳 | E21: 软件部 | F21: 45848 | G21: =VLOOKUP($B21,INDIRECT($D21&"!$AG$1:$AY$66"),MATCH(G$1,INDIRECT($D21&"!$AG$1:$AY$1"),0),0) -> 24 | H21: =VLOOKUP($B21,INDIRECT($D21&"!$AG$1:$AY$66"),MATCH(H$1,INDIRECT($D21&"!$AG$1:$AY$1"),0),0) -> 23 | I21: =VLOOKUP($B21,INDIRECT($D21&"!$AG$1:$AY$66"),MATCH(I$1,INDIRECT($D21&"!$AG$1:$AY$1"),0),0) -> 0 | J21: =VLOOKUP($B21,INDIRECT($D21&"!$AG$1:$AY$66"),MATCH(J$1,INDIRECT($D21&"!$AG$1:$AY$1"),0),0) -> 0 | K21: =VLOOKUP($B21,INDIRECT($D21&"!$AG$1:$AY$66"),MATCH(K$1,INDIRECT($D21&"!$AG$1:$AY$1"),0),0) -> 0 | L21: =VLOOKUP($B21,INDIRECT($D21&"!$AG$1:$AY$66"),MATCH(L$1,INDIRECT($D21&"!$AG$1:$AY$1"),0),0) -> 0 | M21: =VLOOKUP($B21,INDIRECT($D21&"!$AG$1:$AY$66"),MATCH(M$1,INDIRECT($D21&"!$AG$1:$AY$1"),0),0) -> 0 | N21: =VLOOKUP($B21,INDIRECT($D21&"!$AG$1:$AY$66"),MATCH(N$1,INDIRECT($D21&"!$AG$1:$AY$1"),0),0) -> 0 | ... V21: =VLOOKUP($B21,INDIRECT($D21&"!$AG$1:$AY$66"),MATCH(V$1,INDIRECT($D21&"!$AG$1:$AY$1"),0),0) -> 0 | W21: =VLOOKUP($B21,INDIRECT($D21&"!$AG$1:$AY$66"),MATCH(W$2,INDIRECT($D21&"!$AG$1:$AY$1"),0),0) -> 200 | X21: =VLOOKUP($B21,INDIRECT($D21&"!$AG$1:$AY$66"),MATCH(X$1,INDIRECT($D21&"!$AG$1:$AY$1"),0),0) -> 全勤
A22: 7613578648704011195 | B22: 王明宇 | C22: 4 | D22: 深圳 | E22: 软件部 | G22: =VLOOKUP($B22,INDIRECT($D22&"!$AG$1:$AY$66"),MATCH(G$1,INDIRECT($D22&"!$AG$1:$AY$1"),0),0) -> 24 | H22: =VLOOKUP($B22,INDIRECT($D22&"!$AG$1:$AY$66"),MATCH(H$1,INDIRECT($D22&"!$AG$1:$AY$1"),0),0) -> 21.56 | I22: =VLOOKUP($B22,INDIRECT($D22&"!$AG$1:$AY$66"),MATCH(I$1,INDIRECT($D22&"!$AG$1:$AY$1"),0),0) -> 0 | J22: =VLOOKUP($B22,INDIRECT($D22&"!$AG$1:$AY$66"),MATCH(J$1,INDIRECT($D22&"!$AG$1:$AY$1"),0),0) -> 0 | K22: =VLOOKUP($B22,INDIRECT($D22&"!$AG$1:$AY$66"),MATCH(K$1,INDIRECT($D22&"!$AG$1:$AY$1"),0),0) -> 0 | L22: =VLOOKUP($B22,INDIRECT($D22&"!$AG$1:$AY$66"),MATCH(L$1,INDIRECT($D22&"!$AG$1:$AY$1"),0),0) -> 1.44 | M22: =VLOOKUP($B22,INDIRECT($D22&"!$AG$1:$AY$66"),MATCH(M$1,INDIRECT($D22&"!$AG$1:$AY$1"),0),0) -> 0 | N22: =VLOOKUP($B22,INDIRECT($D22&"!$AG$1:$AY$66"),MATCH(N$1,INDIRECT($D22&"!$AG$1:$AY$1"),0),0) -> 0 | ... V22: =VLOOKUP($B22,INDIRECT($D22&"!$AG$1:$AY$66"),MATCH(V$1,INDIRECT($D22&"!$AG$1:$AY$1"),0),0) -> 0 | W22: =VLOOKUP($B22,INDIRECT($D22&"!$AG$1:$AY$66"),MATCH(W$2,INDIRECT($D22&"!$AG$1:$AY$1"),0),0) -> 0 | X22: =VLOOKUP($B22,INDIRECT($D22&"!$AG$1:$AY$66"),MATCH(X$1,INDIRECT($D22&"!$AG$1:$AY$1"),0),0) -> 事假 3.5小时(04/07 09:00-04/07 12:30);事假 8小时(04/16 09:00-04/16 18:30)
A23: 7617656987353992410 | B23: 黄云宝 | C23: 4 | D23: 深圳 | E23: 软件部 | G23: =VLOOKUP($B23,INDIRECT($D23&"!$AG$1:$AY$66"),MATCH(G$1,INDIRECT($D23&"!$AG$1:$AY$1"),0),0) -> 24 | H23: =VLOOKUP($B23,INDIRECT($D23&"!$AG$1:$AY$66"),MATCH(H$1,INDIRECT($D23&"!$AG$1:$AY$1"),0),0) -> 23 | I23: =VLOOKUP($B23,INDIRECT($D23&"!$AG$1:$AY$66"),MATCH(I$1,INDIRECT($D23&"!$AG$1:$AY$1"),0),0) -> 0 | J23: =VLOOKUP($B23,INDIRECT($D23&"!$AG$1:$AY$66"),MATCH(J$1,INDIRECT($D23&"!$AG$1:$AY$1"),0),0) -> 0 | K23: =VLOOKUP($B23,INDIRECT($D23&"!$AG$1:$AY$66"),MATCH(K$1,INDIRECT($D23&"!$AG$1:$AY$1"),0),0) -> 0 | L23: =VLOOKUP($B23,INDIRECT($D23&"!$AG$1:$AY$66"),MATCH(L$1,INDIRECT($D23&"!$AG$1:$AY$1"),0),0) -> 0 | M23: =VLOOKUP($B23,INDIRECT($D23&"!$AG$1:$AY$66"),MATCH(M$1,INDIRECT($D23&"!$AG$1:$AY$1"),0),0) -> 0 | N23: =VLOOKUP($B23,INDIRECT($D23&"!$AG$1:$AY$66"),MATCH(N$1,INDIRECT($D23&"!$AG$1:$AY$1"),0),0) -> 0 | ... V23: =VLOOKUP($B23,INDIRECT($D23&"!$AG$1:$AY$66"),MATCH(V$1,INDIRECT($D23&"!$AG$1:$AY$1"),0),0) -> 0 | W23: =VLOOKUP($B23,INDIRECT($D23&"!$AG$1:$AY$66"),MATCH(W$2,INDIRECT($D23&"!$AG$1:$AY$1"),0),0) -> 200 | X23: =VLOOKUP($B23,INDIRECT($D23&"!$AG$1:$AY$66"),MATCH(X$1,INDIRECT($D23&"!$AG$1:$AY$1"),0),0) -> 全勤
A24: 7494123790910652420 | B24: 耿纪涛 | C24: 4 | D24: 深圳 | E24: 人力资源行政部 | F24: 44696 | G24: =VLOOKUP($B24,INDIRECT($D24&"!$AG$1:$AY$66"),MATCH(G$1,INDIRECT($D24&"!$AG$1:$AY$1"),0),0) -> 24 | H24: =VLOOKUP($B24,INDIRECT($D24&"!$AG$1:$AY$66"),MATCH(H$1,INDIRECT($D24&"!$AG$1:$AY$1"),0),0) -> 23 | I24: =VLOOKUP($B24,INDIRECT($D24&"!$AG$1:$AY$66"),MATCH(I$1,INDIRECT($D24&"!$AG$1:$AY$1"),0),0) -> 0 | J24: =VLOOKUP($B24,INDIRECT($D24&"!$AG$1:$AY$66"),MATCH(J$1,INDIRECT($D24&"!$AG$1:$AY$1"),0),0) -> 0 | K24: =VLOOKUP($B24,INDIRECT($D24&"!$AG$1:$AY$66"),MATCH(K$1,INDIRECT($D24&"!$AG$1:$AY$1"),0),0) -> 0 | L24: =VLOOKUP($B24,INDIRECT($D24&"!$AG$1:$AY$66"),MATCH(L$1,INDIRECT($D24&"!$AG$1:$AY$1"),0),0) -> 0 | M24: =VLOOKUP($B24,INDIRECT($D24&"!$AG$1:$AY$66"),MATCH(M$1,INDIRECT($D24&"!$AG$1:$AY$1"),0),0) -> 0 | N24: =VLOOKUP($B24,INDIRECT($D24&"!$AG$1:$AY$66"),MATCH(N$1,INDIRECT($D24&"!$AG$1:$AY$1"),0),0) -> 0 | ... V24: =VLOOKUP($B24,INDIRECT($D24&"!$AG$1:$AY$66"),MATCH(V$1,INDIRECT($D24&"!$AG$1:$AY$1"),0),0) -> 0 | W24: =VLOOKUP($B24,INDIRECT($D24&"!$AG$1:$AY$66"),MATCH(W$2,INDIRECT($D24&"!$AG$1:$AY$1"),0),0) -> 200 | X24: =VLOOKUP($B24,INDIRECT($D24&"!$AG$1:$AY$66"),MATCH(X$1,INDIRECT($D24&"!$AG$1:$AY$1"),0),0) -> 全勤，加班 4.5小时后调休(04/11 14:00-04/11 18:30)
A25: 7494456825800867843 | B25: 曾华欣 | C25: 4 | D25: 深圳 | E25: 人力资源行政部 | F25: 44958 | G25: =VLOOKUP($B25,INDIRECT($D25&"!$AG$1:$AY$66"),MATCH(G$1,INDIRECT($D25&"!$AG$1:$AY$1"),0),0) -> 24 | H25: =VLOOKUP($B25,INDIRECT($D25&"!$AG$1:$AY$66"),MATCH(H$1,INDIRECT($D25&"!$AG$1:$AY$1"),0),0) -> 22 | I25: =VLOOKUP($B25,INDIRECT($D25&"!$AG$1:$AY$66"),MATCH(I$1,INDIRECT($D25&"!$AG$1:$AY$1"),0),0) -> 0 | J25: =VLOOKUP($B25,INDIRECT($D25&"!$AG$1:$AY$66"),MATCH(J$1,INDIRECT($D25&"!$AG$1:$AY$1"),0),0) -> 0 | K25: =VLOOKUP($B25,INDIRECT($D25&"!$AG$1:$AY$66"),MATCH(K$1,INDIRECT($D25&"!$AG$1:$AY$1"),0),0) -> 0 | L25: =VLOOKUP($B25,INDIRECT($D25&"!$AG$1:$AY$66"),MATCH(L$1,INDIRECT($D25&"!$AG$1:$AY$1"),0),0) -> 0 | M25: =VLOOKUP($B25,INDIRECT($D25&"!$AG$1:$AY$66"),MATCH(M$1,INDIRECT($D25&"!$AG$1:$AY$1"),0),0) -> 1 | N25: =VLOOKUP($B25,INDIRECT($D25&"!$AG$1:$AY$66"),MATCH(N$1,INDIRECT($D25&"!$AG$1:$AY$1"),0),0) -> 0 | ... V25: =VLOOKUP($B25,INDIRECT($D25&"!$AG$1:$AY$66"),MATCH(V$1,INDIRECT($D25&"!$AG$1:$AY$1"),0),0) -> 0 | W25: =VLOOKUP($B25,INDIRECT($D25&"!$AG$1:$AY$66"),MATCH(W$2,INDIRECT($D25&"!$AG$1:$AY$1"),0),0) -> 200 | X25: =VLOOKUP($B25,INDIRECT($D25&"!$AG$1:$AY$66"),MATCH(X$1,INDIRECT($D25&"!$AG$1:$AY$1"),0),0) -> 全勤，年假 8小时(04/18 09:00-04/18 18:30)
A26: 7494103198140399644 | B26: 李冬勤 | C26: 4 | D26: 深圳 | E26: 人力资源行政部 | F26: 45597 | G26: =VLOOKUP($B26,INDIRECT($D26&"!$AG$1:$AY$66"),MATCH(G$1,INDIRECT($D26&"!$AG$1:$AY$1"),0),0) -> 24 | H26: =VLOOKUP($B26,INDIRECT($D26&"!$AG$1:$AY$66"),MATCH(H$1,INDIRECT($D26&"!$AG$1:$AY$1"),0),0) -> 18 | I26: =VLOOKUP($B26,INDIRECT($D26&"!$AG$1:$AY$66"),MATCH(I$1,INDIRECT($D26&"!$AG$1:$AY$1"),0),0) -> 0 | J26: =VLOOKUP($B26,INDIRECT($D26&"!$AG$1:$AY$66"),MATCH(J$1,INDIRECT($D26&"!$AG$1:$AY$1"),0),0) -> 0 | K26: =VLOOKUP($B26,INDIRECT($D26&"!$AG$1:$AY$66"),MATCH(K$1,INDIRECT($D26&"!$AG$1:$AY$1"),0),0) -> 0 | L26: =VLOOKUP($B26,INDIRECT($D26&"!$AG$1:$AY$66"),MATCH(L$1,INDIRECT($D26&"!$AG$1:$AY$1"),0),0) -> 0 | M26: =VLOOKUP($B26,INDIRECT($D26&"!$AG$1:$AY$66"),MATCH(M$1,INDIRECT($D26&"!$AG$1:$AY$1"),0),0) -> 1 | N26: =VLOOKUP($B26,INDIRECT($D26&"!$AG$1:$AY$66"),MATCH(N$1,INDIRECT($D26&"!$AG$1:$AY$1"),0),0) -> 0 | ... V26: =VLOOKUP($B26,INDIRECT($D26&"!$AG$1:$AY$66"),MATCH(V$1,INDIRECT($D26&"!$AG$1:$AY$1"),0),0) -> 0 | W26: =VLOOKUP($B26,INDIRECT($D26&"!$AG$1:$AY$66"),MATCH(W$2,INDIRECT($D26&"!$AG$1:$AY$1"),0),0) -> 0 | X26: =VLOOKUP($B26,INDIRECT($D26&"!$AG$1:$AY$66"),MATCH(X$1,INDIRECT($D26&"!$AG$1:$AY$1"),0),0) -> 本月1-5号产假共5天;年假 8小时(04/23 09:00-04/23 18:30)，按人力行政制度哺乳未满1周岁的孩童每天享有1小时哺乳假。
A27: 7497931957964161052 | B27: 罗洁敏 | C27: 4 | D27: 深圳 | E27: 事业二部/项目二部 | F27: 45169 | G27: =VLOOKUP($B27,INDIRECT($D27&"!$AG$1:$AY$66"),MATCH(G$1,INDIRECT($D27&"!$AG$1:$AY$1"),0),0) -> 24 | H27: =VLOOKUP($B27,INDIRECT($D27&"!$AG$1:$AY$66"),MATCH(H$1,INDIRECT($D27&"!$AG$1:$AY$1"),0),0) -> 22 | I27: =VLOOKUP($B27,INDIRECT($D27&"!$AG$1:$AY$66"),MATCH(I$1,INDIRECT($D27&"!$AG$1:$AY$1"),0),0) -> 0 | J27: =VLOOKUP($B27,INDIRECT($D27&"!$AG$1:$AY$66"),MATCH(J$1,INDIRECT($D27&"!$AG$1:$AY$1"),0),0) -> 0 | K27: =VLOOKUP($B27,INDIRECT($D27&"!$AG$1:$AY$66"),MATCH(K$1,INDIRECT($D27&"!$AG$1:$AY$1"),0),0) -> 0 | L27: =VLOOKUP($B27,INDIRECT($D27&"!$AG$1:$AY$66"),MATCH(L$1,INDIRECT($D27&"!$AG$1:$AY$1"),0),0) -> 1 | M27: =VLOOKUP($B27,INDIRECT($D27&"!$AG$1:$AY$66"),MATCH(M$1,INDIRECT($D27&"!$AG$1:$AY$1"),0),0) -> 0 | N27: =VLOOKUP($B27,INDIRECT($D27&"!$AG$1:$AY$66"),MATCH(N$1,INDIRECT($D27&"!$AG$1:$AY$1"),0),0) -> 0 | ... V27: =VLOOKUP($B27,INDIRECT($D27&"!$AG$1:$AY$66"),MATCH(V$1,INDIRECT($D27&"!$AG$1:$AY$1"),0),0) -> 0 | W27: =VLOOKUP($B27,INDIRECT($D27&"!$AG$1:$AY$66"),MATCH(W$2,INDIRECT($D27&"!$AG$1:$AY$1"),0),0) -> 0 | X27: =VLOOKUP($B27,INDIRECT($D27&"!$AG$1:$AY$66"),MATCH(X$1,INDIRECT($D27&"!$AG$1:$AY$1"),0),0) -> 事假 8小时(04/24 09:00-04/24 18:30)，30日离职
A28: 7497931856088727553 | B28: 李彩花 | C28: 4 | D28: 深圳 | E28: 事业二部/项目二部 | F28: 45486 | G28: =VLOOKUP($B28,INDIRECT($D28&"!$AG$1:$AY$66"),MATCH(G$1,INDIRECT($D28&"!$AG$1:$AY$1"),0),0) -> 24 | H28: =VLOOKUP($B28,INDIRECT($D28&"!$AG$1:$AY$66"),MATCH(H$1,INDIRECT($D28&"!$AG$1:$AY$1"),0),0) -> 22 | I28: =VLOOKUP($B28,INDIRECT($D28&"!$AG$1:$AY$66"),MATCH(I$1,INDIRECT($D28&"!$AG$1:$AY$1"),0),0) -> 0 | J28: =VLOOKUP($B28,INDIRECT($D28&"!$AG$1:$AY$66"),MATCH(J$1,INDIRECT($D28&"!$AG$1:$AY$1"),0),0) -> 0 | K28: =VLOOKUP($B28,INDIRECT($D28&"!$AG$1:$AY$66"),MATCH(K$1,INDIRECT($D28&"!$AG$1:$AY$1"),0),0) -> 0 | L28: =VLOOKUP($B28,INDIRECT($D28&"!$AG$1:$AY$66"),MATCH(L$1,INDIRECT($D28&"!$AG$1:$AY$1"),0),0) -> 0 | M28: =VLOOKUP($B28,INDIRECT($D28&"!$AG$1:$AY$66"),MATCH(M$1,INDIRECT($D28&"!$AG$1:$AY$1"),0),0) -> 1 | N28: =VLOOKUP($B28,INDIRECT($D28&"!$AG$1:$AY$66"),MATCH(N$1,INDIRECT($D28&"!$AG$1:$AY$1"),0),0) -> 0 | ... V28: =VLOOKUP($B28,INDIRECT($D28&"!$AG$1:$AY$66"),MATCH(V$1,INDIRECT($D28&"!$AG$1:$AY$1"),0),0) -> 0 | W28: =VLOOKUP($B28,INDIRECT($D28&"!$AG$1:$AY$66"),MATCH(W$2,INDIRECT($D28&"!$AG$1:$AY$1"),0),0) -> 200 | X28: =VLOOKUP($B28,INDIRECT($D28&"!$AG$1:$AY$66"),MATCH(X$1,INDIRECT($D28&"!$AG$1:$AY$1"),0),0) -> 全勤，年假 8小时(04/22 09:00-04/22 18:30)
A29: 7494099716294082564 | B29: 张雅丽 | C29: 4 | D29: 深圳 | E29: 事业二部/项目五部 | F29: 43577 | G29: =VLOOKUP($B29,INDIRECT($D29&"!$AG$1:$AY$66"),MATCH(G$1,INDIRECT($D29&"!$AG$1:$AY$1"),0),0) -> 24 | H29: =VLOOKUP($B29,INDIRECT($D29&"!$AG$1:$AY$66"),MATCH(H$1,INDIRECT($D29&"!$AG$1:$AY$1"),0),0) -> 22 | I29: =VLOOKUP($B29,INDIRECT($D29&"!$AG$1:$AY$66"),MATCH(I$1,INDIRECT($D29&"!$AG$1:$AY$1"),0),0) -> 0 | J29: =VLOOKUP($B29,INDIRECT($D29&"!$AG$1:$AY$66"),MATCH(J$1,INDIRECT($D29&"!$AG$1:$AY$1"),0),0) -> 0 | K29: =VLOOKUP($B29,INDIRECT($D29&"!$AG$1:$AY$66"),MATCH(K$1,INDIRECT($D29&"!$AG$1:$AY$1"),0),0) -> 0 | L29: =VLOOKUP($B29,INDIRECT($D29&"!$AG$1:$AY$66"),MATCH(L$1,INDIRECT($D29&"!$AG$1:$AY$1"),0),0) -> 0 | M29: =VLOOKUP($B29,INDIRECT($D29&"!$AG$1:$AY$66"),MATCH(M$1,INDIRECT($D29&"!$AG$1:$AY$1"),0),0) -> 1 | N29: =VLOOKUP($B29,INDIRECT($D29&"!$AG$1:$AY$66"),MATCH(N$1,INDIRECT($D29&"!$AG$1:$AY$1"),0),0) -> 0 | ... V29: =VLOOKUP($B29,INDIRECT($D29&"!$AG$1:$AY$66"),MATCH(V$1,INDIRECT($D29&"!$AG$1:$AY$1"),0),0) -> 0 | W29: =VLOOKUP($B29,INDIRECT($D29&"!$AG$1:$AY$66"),MATCH(W$2,INDIRECT($D29&"!$AG$1:$AY$1"),0),0) -> 200 | X29: =VLOOKUP($B29,INDIRECT($D29&"!$AG$1:$AY$66"),MATCH(X$1,INDIRECT($D29&"!$AG$1:$AY$1"),0),0) -> 全勤，年假 8小时(04/20 09:00-04/20 18:30)
A30: 7503732576948797444 | B30: 范婷 | C30: 4 | D30: 深圳 | E30: 事业二部/项目五部 | F30: 45627 | G30: =VLOOKUP($B30,INDIRECT($D30&"!$AG$1:$AY$66"),MATCH(G$1,INDIRECT($D30&"!$AG$1:$AY$1"),0),0) -> 24 | H30: =VLOOKUP($B30,INDIRECT($D30&"!$AG$1:$AY$66"),MATCH(H$1,INDIRECT($D30&"!$AG$1:$AY$1"),0),0) -> 0 | I30: =VLOOKUP($B30,INDIRECT($D30&"!$AG$1:$AY$66"),MATCH(I$1,INDIRECT($D30&"!$AG$1:$AY$1"),0),0) -> 0 | J30: =VLOOKUP($B30,INDIRECT($D30&"!$AG$1:$AY$66"),MATCH(J$1,INDIRECT($D30&"!$AG$1:$AY$1"),0),0) -> 0 | K30: =VLOOKUP($B30,INDIRECT($D30&"!$AG$1:$AY$66"),MATCH(K$1,INDIRECT($D30&"!$AG$1:$AY$1"),0),0) -> 0 | L30: =VLOOKUP($B30,INDIRECT($D30&"!$AG$1:$AY$66"),MATCH(L$1,INDIRECT($D30&"!$AG$1:$AY$1"),0),0) -> 0 | M30: =VLOOKUP($B30,INDIRECT($D30&"!$AG$1:$AY$66"),MATCH(M$1,INDIRECT($D30&"!$AG$1:$AY$1"),0),0) -> 0 | N30: =VLOOKUP($B30,INDIRECT($D30&"!$AG$1:$AY$66"),MATCH(N$1,INDIRECT($D30&"!$AG$1:$AY$1"),0),0) -> 0 | ... V30: =VLOOKUP($B30,INDIRECT($D30&"!$AG$1:$AY$66"),MATCH(V$1,INDIRECT($D30&"!$AG$1:$AY$1"),0),0) -> 0 | W30: =VLOOKUP($B30,INDIRECT($D30&"!$AG$1:$AY$66"),MATCH(W$2,INDIRECT($D30&"!$AG$1:$AY$1"),0),0) -> 0 | X30: =VLOOKUP($B30,INDIRECT($D30&"!$AG$1:$AY$66"),MATCH(X$1,INDIRECT($D30&"!$AG$1:$AY$1"),0),0) -> 产假 178天(01/05 上午-07/01 下午)
A31: 7497916191278645251 | B31: 张芮 | C31: 4 | D31: 深圳 | E31: 事业二部/项目五部 | F31: 45901 | G31: =VLOOKUP($B31,INDIRECT($D31&"!$AG$1:$AY$66"),MATCH(G$1,INDIRECT($D31&"!$AG$1:$AY$1"),0),0) -> 24 | H31: =VLOOKUP($B31,INDIRECT($D31&"!$AG$1:$AY$66"),MATCH(H$1,INDIRECT($D31&"!$AG$1:$AY$1"),0),0) -> 23 | I31: =VLOOKUP($B31,INDIRECT($D31&"!$AG$1:$AY$66"),MATCH(I$1,INDIRECT($D31&"!$AG$1:$AY$1"),0),0) -> 0 | J31: =VLOOKUP($B31,INDIRECT($D31&"!$AG$1:$AY$66"),MATCH(J$1,INDIRECT($D31&"!$AG$1:$AY$1"),0),0) -> 0 | K31: =VLOOKUP($B31,INDIRECT($D31&"!$AG$1:$AY$66"),MATCH(K$1,INDIRECT($D31&"!$AG$1:$AY$1"),0),0) -> 0 | L31: =VLOOKUP($B31,INDIRECT($D31&"!$AG$1:$AY$66"),MATCH(L$1,INDIRECT($D31&"!$AG$1:$AY$1"),0),0) -> 0 | M31: =VLOOKUP($B31,INDIRECT($D31&"!$AG$1:$AY$66"),MATCH(M$1,INDIRECT($D31&"!$AG$1:$AY$1"),0),0) -> 0 | N31: =VLOOKUP($B31,INDIRECT($D31&"!$AG$1:$AY$66"),MATCH(N$1,INDIRECT($D31&"!$AG$1:$AY$1"),0),0) -> 0 | ... V31: =VLOOKUP($B31,INDIRECT($D31&"!$AG$1:$AY$66"),MATCH(V$1,INDIRECT($D31&"!$AG$1:$AY$1"),0),0) -> 0 | W31: =VLOOKUP($B31,INDIRECT($D31&"!$AG$1:$AY$66"),MATCH(W$2,INDIRECT($D31&"!$AG$1:$AY$1"),0),0) -> 200 | X31: =VLOOKUP($B31,INDIRECT($D31&"!$AG$1:$AY$66"),MATCH(X$1,INDIRECT($D31&"!$AG$1:$AY$1"),0),0) -> 全勤
A32: 7539724651969773596 | B32: 杨琴 | C32: 4 | D32: 深圳 | E32: 事业二部/项目五部 | F32: 46071 | G32: =VLOOKUP($B32,INDIRECT($D32&"!$AG$1:$AY$66"),MATCH(G$1,INDIRECT($D32&"!$AG$1:$AY$1"),0),0) -> 24 | H32: =VLOOKUP($B32,INDIRECT($D32&"!$AG$1:$AY$66"),MATCH(H$1,INDIRECT($D32&"!$AG$1:$AY$1"),0),0) -> 19 | I32: =VLOOKUP($B32,INDIRECT($D32&"!$AG$1:$AY$66"),MATCH(I$1,INDIRECT($D32&"!$AG$1:$AY$1"),0),0) -> 10 | J32: =VLOOKUP($B32,INDIRECT($D32&"!$AG$1:$AY$66"),MATCH(J$1,INDIRECT($D32&"!$AG$1:$AY$1"),0),0) -> 1 | K32: =VLOOKUP($B32,INDIRECT($D32&"!$AG$1:$AY$66"),MATCH(K$1,INDIRECT($D32&"!$AG$1:$AY$1"),0),0) -> 0 | L32: =VLOOKUP($B32,INDIRECT($D32&"!$AG$1:$AY$66"),MATCH(L$1,INDIRECT($D32&"!$AG$1:$AY$1"),0),0) -> 0 | M32: =VLOOKUP($B32,INDIRECT($D32&"!$AG$1:$AY$66"),MATCH(M$1,INDIRECT($D32&"!$AG$1:$AY$1"),0),0) -> 0 | N32: =VLOOKUP($B32,INDIRECT($D32&"!$AG$1:$AY$66"),MATCH(N$1,INDIRECT($D32&"!$AG$1:$AY$1"),0),0) -> 4 | ... V32: =VLOOKUP($B32,INDIRECT($D32&"!$AG$1:$AY$66"),MATCH(V$1,INDIRECT($D32&"!$AG$1:$AY$1"),0),0) -> 0 | W32: =VLOOKUP($B32,INDIRECT($D32&"!$AG$1:$AY$66"),MATCH(W$2,INDIRECT($D32&"!$AG$1:$AY$1"),0),0) -> 0 | X32: =VLOOKUP($B32,INDIRECT($D32&"!$AG$1:$AY$66"),MATCH(X$1,INDIRECT($D32&"!$AG$1:$AY$1"),0),0) -> 病假 32小时(04/01 09:00-04/04 18:30)，缺卡1次，迟到2次共10分钟
A33: 7559020197085511682 | B33: 文奕凡 | C33: 4 | D33: 深圳 | E33: 事业二部/项目二部 | F33: 46121 | G33: =VLOOKUP($B33,INDIRECT($D33&"!$AG$1:$AY$66"),MATCH(G$1,INDIRECT($D33&"!$AG$1:$AY$1"),0),0) -> 24 | H33: =VLOOKUP($B33,INDIRECT($D33&"!$AG$1:$AY$66"),MATCH(H$1,INDIRECT($D33&"!$AG$1:$AY$1"),0),0) -> 22 | I33: =VLOOKUP($B33,INDIRECT($D33&"!$AG$1:$AY$66"),MATCH(I$1,INDIRECT($D33&"!$AG$1:$AY$1"),0),0) -> 4 | J33: =VLOOKUP($B33,INDIRECT($D33&"!$AG$1:$AY$66"),MATCH(J$1,INDIRECT($D33&"!$AG$1:$AY$1"),0),0) -> 0 | K33: =VLOOKUP($B33,INDIRECT($D33&"!$AG$1:$AY$66"),MATCH(K$1,INDIRECT($D33&"!$AG$1:$AY$1"),0),0) -> 0 | L33: =VLOOKUP($B33,INDIRECT($D33&"!$AG$1:$AY$66"),MATCH(L$1,INDIRECT($D33&"!$AG$1:$AY$1"),0),0) -> 0 | M33: =VLOOKUP($B33,INDIRECT($D33&"!$AG$1:$AY$66"),MATCH(M$1,INDIRECT($D33&"!$AG$1:$AY$1"),0),0) -> 0 | N33: =VLOOKUP($B33,INDIRECT($D33&"!$AG$1:$AY$66"),MATCH(N$1,INDIRECT($D33&"!$AG$1:$AY$1"),0),0) -> 1 | ... V33: =VLOOKUP($B33,INDIRECT($D33&"!$AG$1:$AY$66"),MATCH(V$1,INDIRECT($D33&"!$AG$1:$AY$1"),0),0) -> 0 | W33: =VLOOKUP($B33,INDIRECT($D33&"!$AG$1:$AY$66"),MATCH(W$2,INDIRECT($D33&"!$AG$1:$AY$1"),0),0) -> 0 | X33: =VLOOKUP($B33,INDIRECT($D33&"!$AG$1:$AY$66"),MATCH(X$1,INDIRECT($D33&"!$AG$1:$AY$1"),0),0) -> 病假 8小时(04/21 09:00-04/21 18:30)，迟到3次共4分钟
A34: 7497922022561366020 | B34: 陈晓波 | C34: 4 | D34: 深圳 | E34: 事业六部/项目六部 | F34: 42705 | G34: =VLOOKUP($B34,INDIRECT($D34&"!$AG$1:$AY$66"),MATCH(G$1,INDIRECT($D34&"!$AG$1:$AY$1"),0),0) -> 24 | H34: =VLOOKUP($B34,INDIRECT($D34&"!$AG$1:$AY$66"),MATCH(H$1,INDIRECT($D34&"!$AG$1:$AY$1"),0),0) -> 22.44 | I34: =VLOOKUP($B34,INDIRECT($D34&"!$AG$1:$AY$66"),MATCH(I$1,INDIRECT($D34&"!$AG$1:$AY$1"),0),0) -> 0 | J34: =VLOOKUP($B34,INDIRECT($D34&"!$AG$1:$AY$66"),MATCH(J$1,INDIRECT($D34&"!$AG$1:$AY$1"),0),0) -> 0 | K34: =VLOOKUP($B34,INDIRECT($D34&"!$AG$1:$AY$66"),MATCH(K$1,INDIRECT($D34&"!$AG$1:$AY$1"),0),0) -> 0 | L34: =VLOOKUP($B34,INDIRECT($D34&"!$AG$1:$AY$66"),MATCH(L$1,INDIRECT($D34&"!$AG$1:$AY$1"),0),0) -> 0 | M34: =VLOOKUP($B34,INDIRECT($D34&"!$AG$1:$AY$66"),MATCH(M$1,INDIRECT($D34&"!$AG$1:$AY$1"),0),0) -> 0.56 | N34: =VLOOKUP($B34,INDIRECT($D34&"!$AG$1:$AY$66"),MATCH(N$1,INDIRECT($D34&"!$AG$1:$AY$1"),0),0) -> 0 | ... V34: =VLOOKUP($B34,INDIRECT($D34&"!$AG$1:$AY$66"),MATCH(V$1,INDIRECT($D34&"!$AG$1:$AY$1"),0),0) -> 0 | W34: =VLOOKUP($B34,INDIRECT($D34&"!$AG$1:$AY$66"),MATCH(W$2,INDIRECT($D34&"!$AG$1:$AY$1"),0),0) -> 200 | X34: =VLOOKUP($B34,INDIRECT($D34&"!$AG$1:$AY$66"),MATCH(X$1,INDIRECT($D34&"!$AG$1:$AY$1"),0),0) -> 全勤，年假 4.5小时(04/17 14:00-04/17 18:30)
A35: 7497920080774873107 | B35: 卢丹婷 | C35: 4 | D35: 深圳 | E35: 事业六部/项目六部 | F35: 43739 | G35: =VLOOKUP($B35,INDIRECT($D35&"!$AG$1:$AY$66"),MATCH(G$1,INDIRECT($D35&"!$AG$1:$AY$1"),0),0) -> 24 | H35: =VLOOKUP($B35,INDIRECT($D35&"!$AG$1:$AY$66"),MATCH(H$1,INDIRECT($D35&"!$AG$1:$AY$1"),0),0) -> 22.44 | I35: =VLOOKUP($B35,INDIRECT($D35&"!$AG$1:$AY$66"),MATCH(I$1,INDIRECT($D35&"!$AG$1:$AY$1"),0),0) -> 0 | J35: =VLOOKUP($B35,INDIRECT($D35&"!$AG$1:$AY$66"),MATCH(J$1,INDIRECT($D35&"!$AG$1:$AY$1"),0),0) -> 0 | K35: =VLOOKUP($B35,INDIRECT($D35&"!$AG$1:$AY$66"),MATCH(K$1,INDIRECT($D35&"!$AG$1:$AY$1"),0),0) -> 0 | L35: =VLOOKUP($B35,INDIRECT($D35&"!$AG$1:$AY$66"),MATCH(L$1,INDIRECT($D35&"!$AG$1:$AY$1"),0),0) -> 0 | M35: =VLOOKUP($B35,INDIRECT($D35&"!$AG$1:$AY$66"),MATCH(M$1,INDIRECT($D35&"!$AG$1:$AY$1"),0),0) -> 0.56 | N35: =VLOOKUP($B35,INDIRECT($D35&"!$AG$1:$AY$66"),MATCH(N$1,INDIRECT($D35&"!$AG$1:$AY$1"),0),0) -> 0 | ... V35: =VLOOKUP($B35,INDIRECT($D35&"!$AG$1:$AY$66"),MATCH(V$1,INDIRECT($D35&"!$AG$1:$AY$1"),0),0) -> 0 | W35: =VLOOKUP($B35,INDIRECT($D35&"!$AG$1:$AY$66"),MATCH(W$2,INDIRECT($D35&"!$AG$1:$AY$1"),0),0) -> 200 | X35: =VLOOKUP($B35,INDIRECT($D35&"!$AG$1:$AY$66"),MATCH(X$1,INDIRECT($D35&"!$AG$1:$AY$1"),0),0) -> 全勤，年假 4.5小时(04/17 14:00-04/17 18:30)
... A49: 7497916813032767507 | B49: 陈丹敏 | C49: 4 | D49: 深圳 | E49: 事业四部/项目一部/精品一部 | F49: 44348 | G49: =VLOOKUP($B49,INDIRECT($D49&"!$AG$1:$AY$66"),MATCH(G$1,INDIRECT($D49&"!$AG$1:$AY$1"),0),0) -> 24 | H49: =VLOOKUP($B49,INDIRECT($D49&"!$AG$1:$AY$66"),MATCH(H$1,INDIRECT($D49&"!$AG$1:$AY$1"),0),0) -> 22.56 | I49: =VLOOKUP($B49,INDIRECT($D49&"!$AG$1:$AY$66"),MATCH(I$1,INDIRECT($D49&"!$AG$1:$AY$1"),0),0) -> 0 | J49: =VLOOKUP($B49,INDIRECT($D49&"!$AG$1:$AY$66"),MATCH(J$1,INDIRECT($D49&"!$AG$1:$AY$1"),0),0) -> 0 | K49: =VLOOKUP($B49,INDIRECT($D49&"!$AG$1:$AY$66"),MATCH(K$1,INDIRECT($D49&"!$AG$1:$AY$1"),0),0) -> 0 | L49: =VLOOKUP($B49,INDIRECT($D49&"!$AG$1:$AY$66"),MATCH(L$1,INDIRECT($D49&"!$AG$1:$AY$1"),0),0) -> 0 | M49: =VLOOKUP($B49,INDIRECT($D49&"!$AG$1:$AY$66"),MATCH(M$1,INDIRECT($D49&"!$AG$1:$AY$1"),0),0) -> 0.44 | N49: =VLOOKUP($B49,INDIRECT($D49&"!$AG$1:$AY$66"),MATCH(N$1,INDIRECT($D49&"!$AG$1:$AY$1"),0),0) -> 0 | ... V49: =VLOOKUP($B49,INDIRECT($D49&"!$AG$1:$AY$66"),MATCH(V$1,INDIRECT($D49&"!$AG$1:$AY$1"),0),0) -> 0 | W49: =VLOOKUP($B49,INDIRECT($D49&"!$AG$1:$AY$66"),MATCH(W$2,INDIRECT($D49&"!$AG$1:$AY$1"),0),0) -> 200 | X49: =VLOOKUP($B49,INDIRECT($D49&"!$AG$1:$AY$66"),MATCH(X$1,INDIRECT($D49&"!$AG$1:$AY$1"),0),0) -> 全勤，年假 3.5小时(04/28 09:00-04/28 12:30)
A50: 7596871279270071235 | B50: 姚源 | C50: 4 | D50: 深圳 | E50: 事业四部/项目一部/精品一部 | G50: =VLOOKUP($B50,INDIRECT($D50&"!$AG$1:$AY$66"),MATCH(G$1,INDIRECT($D50&"!$AG$1:$AY$1"),0),0) -> 24 | H50: =VLOOKUP($B50,INDIRECT($D50&"!$AG$1:$AY$66"),MATCH(H$1,INDIRECT($D50&"!$AG$1:$AY$1"),0),0) -> 23 | I50: =VLOOKUP($B50,INDIRECT($D50&"!$AG$1:$AY$66"),MATCH(I$1,INDIRECT($D50&"!$AG$1:$AY$1"),0),0) -> 0 | J50: =VLOOKUP($B50,INDIRECT($D50&"!$AG$1:$AY$66"),MATCH(J$1,INDIRECT($D50&"!$AG$1:$AY$1"),0),0) -> 0 | K50: =VLOOKUP($B50,INDIRECT($D50&"!$AG$1:$AY$66"),MATCH(K$1,INDIRECT($D50&"!$AG$1:$AY$1"),0),0) -> 0 | L50: =VLOOKUP($B50,INDIRECT($D50&"!$AG$1:$AY$66"),MATCH(L$1,INDIRECT($D50&"!$AG$1:$AY$1"),0),0) -> 0 | M50: =VLOOKUP($B50,INDIRECT($D50&"!$AG$1:$AY$66"),MATCH(M$1,INDIRECT($D50&"!$AG$1:$AY$1"),0),0) -> 0 | N50: =VLOOKUP($B50,INDIRECT($D50&"!$AG$1:$AY$66"),MATCH(N$1,INDIRECT($D50&"!$AG$1:$AY$1"),0),0) -> 0 | ... V50: =VLOOKUP($B50,INDIRECT($D50&"!$AG$1:$AY$66"),MATCH(V$1,INDIRECT($D50&"!$AG$1:$AY$1"),0),0) -> 0 | W50: =VLOOKUP($B50,INDIRECT($D50&"!$AG$1:$AY$66"),MATCH(W$2,INDIRECT($D50&"!$AG$1:$AY$1"),0),0) -> 200 | X50: =VLOOKUP($B50,INDIRECT($D50&"!$AG$1:$AY$66"),MATCH(X$1,INDIRECT($D50&"!$AG$1:$AY$1"),0),0) -> 全勤
A51: 7622851945419164882 | B51: 邓佳琪 | C51: 4 | D51: 深圳 | E51: 事业四部/项目一部/精品一部 | G51: =VLOOKUP($B51,INDIRECT($D51&"!$AG$1:$AY$66"),MATCH(G$1,INDIRECT($D51&"!$AG$1:$AY$1"),0),0) -> 24 | H51: =VLOOKUP($B51,INDIRECT($D51&"!$AG$1:$AY$66"),MATCH(H$1,INDIRECT($D51&"!$AG$1:$AY$1"),0),0) -> 23 | I51: =VLOOKUP($B51,INDIRECT($D51&"!$AG$1:$AY$66"),MATCH(I$1,INDIRECT($D51&"!$AG$1:$AY$1"),0),0) -> 0 | J51: =VLOOKUP($B51,INDIRECT($D51&"!$AG$1:$AY$66"),MATCH(J$1,INDIRECT($D51&"!$AG$1:$AY$1"),0),0) -> 0 | K51: =VLOOKUP($B51,INDIRECT($D51&"!$AG$1:$AY$66"),MATCH(K$1,INDIRECT($D51&"!$AG$1:$AY$1"),0),0) -> 0 | L51: =VLOOKUP($B51,INDIRECT($D51&"!$AG$1:$AY$66"),MATCH(L$1,INDIRECT($D51&"!$AG$1:$AY$1"),0),0) -> 0 | M51: =VLOOKUP($B51,INDIRECT($D51&"!$AG$1:$AY$66"),MATCH(M$1,INDIRECT($D51&"!$AG$1:$AY$1"),0),0) -> 0 | N51: =VLOOKUP($B51,INDIRECT($D51&"!$AG$1:$AY$66"),MATCH(N$1,INDIRECT($D51&"!$AG$1:$AY$1"),0),0) -> 0 | ... V51: =VLOOKUP($B51,INDIRECT($D51&"!$AG$1:$AY$66"),MATCH(V$1,INDIRECT($D51&"!$AG$1:$AY$1"),0),0) -> 0 | W51: =VLOOKUP($B51,INDIRECT($D51&"!$AG$1:$AY$66"),MATCH(W$2,INDIRECT($D51&"!$AG$1:$AY$1"),0),0) -> 200 | X51: =VLOOKUP($B51,INDIRECT($D51&"!$AG$1:$AY$66"),MATCH(X$1,INDIRECT($D51&"!$AG$1:$AY$1"),0),0) -> 全勤
A52: 7514862711000760323 | B52: 邝碧琪 | C52: 4 | D52: 深圳 | E52: 事业三部/项目八部 | F52: 45881 | G52: =VLOOKUP($B52,INDIRECT($D52&"!$AG$1:$AY$66"),MATCH(G$1,INDIRECT($D52&"!$AG$1:$AY$1"),0),0) -> 24 | H52: =VLOOKUP($B52,INDIRECT($D52&"!$AG$1:$AY$66"),MATCH(H$1,INDIRECT($D52&"!$AG$1:$AY$1"),0),0) -> 23 | I52: =VLOOKUP($B52,INDIRECT($D52&"!$AG$1:$AY$66"),MATCH(I$1,INDIRECT($D52&"!$AG$1:$AY$1"),0),0) -> 0 | J52: =VLOOKUP($B52,INDIRECT($D52&"!$AG$1:$AY$66"),MATCH(J$1,INDIRECT($D52&"!$AG$1:$AY$1"),0),0) -> 0 | K52: =VLOOKUP($B52,INDIRECT($D52&"!$AG$1:$AY$66"),MATCH(K$1,INDIRECT($D52&"!$AG$1:$AY$1"),0),0) -> 0 | L52: =VLOOKUP($B52,INDIRECT($D52&"!$AG$1:$AY$66"),MATCH(L$1,INDIRECT($D52&"!$AG$1:$AY$1"),0),0) -> 0 | M52: =VLOOKUP($B52,INDIRECT($D52&"!$AG$1:$AY$66"),MATCH(M$1,INDIRECT($D52&"!$AG$1:$AY$1"),0),0) -> 0 | N52: =VLOOKUP($B52,INDIRECT($D52&"!$AG$1:$AY$66"),MATCH(N$1,INDIRECT($D52&"!$AG$1:$AY$1"),0),0) -> 0 | ... V52: =VLOOKUP($B52,INDIRECT($D52&"!$AG$1:$AY$66"),MATCH(V$1,INDIRECT($D52&"!$AG$1:$AY$1"),0),0) -> 0 | W52: =VLOOKUP($B52,INDIRECT($D52&"!$AG$1:$AY$66"),MATCH(W$2,INDIRECT($D52&"!$AG$1:$AY$1"),0),0) -> 200 | X52: =VLOOKUP($B52,INDIRECT($D52&"!$AG$1:$AY$66"),MATCH(X$1,INDIRECT($D52&"!$AG$1:$AY$1"),0),0) -> 全勤
A53: 7494113373470556162 | B53: 彭志荣 | C53: 4 | D53: 仓库 | E53: 仓储部FBA | F53: 44546 | G53: =VLOOKUP($B53,INDIRECT($D53&"!$AG$1:$AY$66"),MATCH(G$1,INDIRECT($D53&"!$AG$1:$AY$1"),0),0) -> 24 | H53: =VLOOKUP($B53,INDIRECT($D53&"!$AG$1:$AY$66"),MATCH(H$1,INDIRECT($D53&"!$AG$1:$AY$1"),0),0) -> 23 | I53: =VLOOKUP($B53,INDIRECT($D53&"!$AG$1:$AY$66"),MATCH(I$1,INDIRECT($D53&"!$AG$1:$AY$1"),0),0) -> 0 | J53: =VLOOKUP($B53,INDIRECT($D53&"!$AG$1:$AY$66"),MATCH(J$1,INDIRECT($D53&"!$AG$1:$AY$1"),0),0) -> 0 | K53: =VLOOKUP($B53,INDIRECT($D53&"!$AG$1:$AY$66"),MATCH(K$1,INDIRECT($D53&"!$AG$1:$AY$1"),0),0) -> 0 | L53: =VLOOKUP($B53,INDIRECT($D53&"!$AG$1:$AY$66"),MATCH(L$1,INDIRECT($D53&"!$AG$1:$AY$1"),0),0) -> 0 | M53: =VLOOKUP($B53,INDIRECT($D53&"!$AG$1:$AY$66"),MATCH(M$1,INDIRECT($D53&"!$AG$1:$AY$1"),0),0) -> 0 | N53: =VLOOKUP($B53,INDIRECT($D53&"!$AG$1:$AY$66"),MATCH(N$1,INDIRECT($D53&"!$AG$1:$AY$1"),0),0) -> 0 | ... V53: =VLOOKUP($B53,INDIRECT($D53&"!$AG$1:$AY$66"),MATCH(V$1,INDIRECT($D53&"!$AG$1:$AY$1"),0),0) -> 0 | W53: =VLOOKUP($B53,INDIRECT($D53&"!$AG$1:$AY$66"),MATCH(W$2,INDIRECT($D53&"!$AG$1:$AY$1"),0),0) -> 200 | X53: =VLOOKUP($B53,INDIRECT($D53&"!$AG$1:$AY$66"),MATCH(X$1,INDIRECT($D53&"!$AG$1:$AY$1"),0),0) -> 全勤
...

Sheet 4月考勤汇总表
A1: 序号 | B1: 姓名 | C1: 月份 | D1: 区域 | E1: 部门 | F1: 转正时间 | G1: 应出勤天数 | H1: 实出勤天数 | I1: 迟到/早退时长(分钟） | J1: 缺卡次数 | K1: 旷工/天 | L1: 事假/天 | M1: 年假/天 | N1: 病假/天 | O1: 丧假/天 | P1: 婚假/天 | Q1: 产假/天 | R1: 调休/天 | S1: 加班/天 | T1: 法定节假日/天 | U1: 计薪天数 | V1: 乐捐/元 | W1: 补贴部分 | X1: 扣款部分 | AA1: 备注 | AB1: 加班总时长/小时
W2: 全勤奖（元） | X2: 社保 | Y2: 公积金 | Z2: 水电费
A3: 1 | B3: 熊文文 | C3: 4 | D3: 深圳 | E3: 财务部 | F3: 44552 | G3: =VLOOKUP($B3,INDIRECT($D3&"!$AG$1:$AY$66"),MATCH(G$1,INDIRECT($D3&"!$AG$1:$AY$1"),0),0) -> 24 | H3: =VLOOKUP($B3,INDIRECT($D3&"!$AG$1:$AY$66"),MATCH(H$1,INDIRECT($D3&"!$AG$1:$AY$1"),0),0) -> 22 | I3: =VLOOKUP($B3,INDIRECT($D3&"!$AG$1:$AY$66"),MATCH(I$1,INDIRECT($D3&"!$AG$1:$AY$1"),0),0) -> 0 | J3: =VLOOKUP($B3,INDIRECT($D3&"!$AG$1:$AY$66"),MATCH(J$1,INDIRECT($D3&"!$AG$1:$AY$1"),0),0) -> 0 | K3: =VLOOKUP($B3,INDIRECT($D3&"!$AG$1:$AY$66"),MATCH(K$1,INDIRECT($D3&"!$AG$1:$AY$1"),0),0) -> 0 | L3: =VLOOKUP($B3,INDIRECT($D3&"!$AG$1:$AY$66"),MATCH(L$1,INDIRECT($D3&"!$AG$1:$AY$1"),0),0) -> 0 | M3: =VLOOKUP($B3,INDIRECT($D3&"!$AG$1:$AY$66"),MATCH(M$1,INDIRECT($D3&"!$AG$1:$AY$1"),0),0) -> 1 | N3: =VLOOKUP($B3,INDIRECT($D3&"!$AG$1:$AY$66"),MATCH(N$1,INDIRECT($D3&"!$AG$1:$AY$1"),0),0) -> 0 | ... V3: =VLOOKUP($B3,INDIRECT($D3&"!$AG$1:$AY$66"),MATCH(V$1,INDIRECT($D3&"!$AG$1:$AY$1"),0),0) -> 0 | W3: =VLOOKUP($B3,INDIRECT($D3&"!$AG$1:$AY$66"),MATCH(W$2,INDIRECT($D3&"!$AG$1:$AY$1"),0),0) -> 200 | X3: =IFERROR(_xlfn.XLOOKUP($B3,社保汇总表!B:B,社保汇总表!G:G),0) -> 420.68 | Y3: =VLOOKUP($B3,公积金汇总表!$P:$Q,2,0) -> 118 | AA3: =VLOOKUP($B3,INDIRECT($D3&"!$AG$1:$AZ$66"),MATCH(AA$1,INDIRECT($D3&"!$AG$1:$AZ$1"),0),0) -> 全勤，年假 8小时(04/20 09:00-04/20 18:30) | AB3: =VLOOKUP($B3,INDIRECT($D3&"!$AG$1:$AZ$66"),MATCH(AB$1,INDIRECT($D3&"!$AG$1:$AZ$1"),0),0) -> 20
A4: 2 | B4: 陈春叶 | C4: 4 | D4: 深圳 | E4: 财务部 | F4: 45727 | G4: =VLOOKUP($B4,INDIRECT($D4&"!$AG$1:$AY$66"),MATCH(G$1,INDIRECT($D4&"!$AG$1:$AY$1"),0),0) -> 24 | H4: =VLOOKUP($B4,INDIRECT($D4&"!$AG$1:$AY$66"),MATCH(H$1,INDIRECT($D4&"!$AG$1:$AY$1"),0),0) -> 22 | I4: =VLOOKUP($B4,INDIRECT($D4&"!$AG$1:$AY$66"),MATCH(I$1,INDIRECT($D4&"!$AG$1:$AY$1"),0),0) -> 0 | J4: =VLOOKUP($B4,INDIRECT($D4&"!$AG$1:$AY$66"),MATCH(J$1,INDIRECT($D4&"!$AG$1:$AY$1"),0),0) -> 0 | K4: =VLOOKUP($B4,INDIRECT($D4&"!$AG$1:$AY$66"),MATCH(K$1,INDIRECT($D4&"!$AG$1:$AY$1"),0),0) -> 0 | L4: =VLOOKUP($B4,INDIRECT($D4&"!$AG$1:$AY$66"),MATCH(L$1,INDIRECT($D4&"!$AG$1:$AY$1"),0),0) -> 0 | M4: =VLOOKUP($B4,INDIRECT($D4&"!$AG$1:$AY$66"),MATCH(M$1,INDIRECT($D4&"!$AG$1:$AY$1"),0),0) -> 1 | N4: =VLOOKUP($B4,INDIRECT($D4&"!$AG$1:$AY$66"),MATCH(N$1,INDIRECT($D4&"!$AG$1:$AY$1"),0),0) -> 0 | ... V4: =VLOOKUP($B4,INDIRECT($D4&"!$AG$1:$AY$66"),MATCH(V$1,INDIRECT($D4&"!$AG$1:$AY$1"),0),0) -> 0 | W4: =VLOOKUP($B4,INDIRECT($D4&"!$AG$1:$AY$66"),MATCH(W$2,INDIRECT($D4&"!$AG$1:$AY$1"),0),0) -> 200 | X4: =IFERROR(_xlfn.XLOOKUP($B4,社保汇总表!B:B,社保汇总表!G:G),0) -> 420.68 | Y4: =VLOOKUP($B4,公积金汇总表!$P:$Q,2,0) -> 118 | AA4: =VLOOKUP($B4,INDIRECT($D4&"!$AG$1:$AY$66"),MATCH(AA$1,INDIRECT($D4&"!$AG$1:$AY$1"),0),0) -> 全勤，外出 4.5小时(04/03 14:00-04/03 18:30);外出 6.5小时(04/22 12:00-04/22 18:30);年假 8小时(04/24 09:00-04/24 18:30) | AB4: =VLOOKUP($B4,INDIRECT($D4&"!$AG$1:$AZ$66"),MATCH(AB$1,INDIRECT($D4&"!$AG$1:$AZ$1"),0),0) -> 0
A5: 3 | B5: 罗倩 | C5: 4 | D5: 深圳 | E5: 财务部 | F5: 46134 | G5: =VLOOKUP($B5,INDIRECT($D5&"!$AG$1:$AY$66"),MATCH(G$1,INDIRECT($D5&"!$AG$1:$AY$1"),0),0) -> 24 | H5: =VLOOKUP($B5,INDIRECT($D5&"!$AG$1:$AY$66"),MATCH(H$1,INDIRECT($D5&"!$AG$1:$AY$1"),0),0) -> 23 | I5: =VLOOKUP($B5,INDIRECT($D5&"!$AG$1:$AY$66"),MATCH(I$1,INDIRECT($D5&"!$AG$1:$AY$1"),0),0) -> 0 | J5: =VLOOKUP($B5,INDIRECT($D5&"!$AG$1:$AY$66"),MATCH(J$1,INDIRECT($D5&"!$AG$1:$AY$1"),0),0) -> 0 | K5: =VLOOKUP($B5,INDIRECT($D5&"!$AG$1:$AY$66"),MATCH(K$1,INDIRECT($D5&"!$AG$1:$AY$1"),0),0) -> 0 | L5: =VLOOKUP($B5,INDIRECT($D5&"!$AG$1:$AY$66"),MATCH(L$1,INDIRECT($D5&"!$AG$1:$AY$1"),0),0) -> 0 | M5: =VLOOKUP($B5,INDIRECT($D5&"!$AG$1:$AY$66"),MATCH(M$1,INDIRECT($D5&"!$AG$1:$AY$1"),0),0) -> 0 | N5: =VLOOKUP($B5,INDIRECT($D5&"!$AG$1:$AY$66"),MATCH(N$1,INDIRECT($D5&"!$AG$1:$AY$1"),0),0) -> 0 | ... V5: =VLOOKUP($B5,INDIRECT($D5&"!$AG$1:$AY$66"),MATCH(V$1,INDIRECT($D5&"!$AG$1:$AY$1"),0),0) -> 0 | W5: =VLOOKUP($B5,INDIRECT($D5&"!$AG$1:$AY$66"),MATCH(W$2,INDIRECT($D5&"!$AG$1:$AY$1"),0),0) -> 200 | X5: =IFERROR(_xlfn.XLOOKUP($B5,社保汇总表!B:B,社保汇总表!G:G),0) -> 521.58 | Y5: =VLOOKUP($B5,公积金汇总表!$P:$Q,2,0) -> 126 | AA5: =VLOOKUP($B5,INDIRECT($D5&"!$AG$1:$AY$66"),MATCH(AA$1,INDIRECT($D5&"!$AG$1:$AY$1"),0),0) -> 全勤，外出 1.5小时(04/28 10:30-04/28 12:00) | AB5: =VLOOKUP($B5,INDIRECT($D5&"!$AG$1:$AZ$66"),MATCH(AB$1,INDIRECT($D5&"!$AG$1:$AZ$1"),0),0) -> 18.5
A6: 4 | B6: 李佳凤 | C6: 4 | D6: 深圳 | E6: 财务部 | G6: =VLOOKUP($B6,INDIRECT($D6&"!$AG$1:$AY$66"),MATCH(G$1,INDIRECT($D6&"!$AG$1:$AY$1"),0),0) -> 24 | H6: =VLOOKUP($B6,INDIRECT($D6&"!$AG$1:$AY$66"),MATCH(H$1,INDIRECT($D6&"!$AG$1:$AY$1"),0),0) -> 23 | I6: =VLOOKUP($B6,INDIRECT($D6&"!$AG$1:$AY$66"),MATCH(I$1,INDIRECT($D6&"!$AG$1:$AY$1"),0),0) -> 0 | J6: =VLOOKUP($B6,INDIRECT($D6&"!$AG$1:$AY$66"),MATCH(J$1,INDIRECT($D6&"!$AG$1:$AY$1"),0),0) -> 0 | K6: =VLOOKUP($B6,INDIRECT($D6&"!$AG$1:$AY$66"),MATCH(K$1,INDIRECT($D6&"!$AG$1:$AY$1"),0),0) -> 0 | L6: =VLOOKUP($B6,INDIRECT($D6&"!$AG$1:$AY$66"),MATCH(L$1,INDIRECT($D6&"!$AG$1:$AY$1"),0),0) -> 0 | M6: =VLOOKUP($B6,INDIRECT($D6&"!$AG$1:$AY$66"),MATCH(M$1,INDIRECT($D6&"!$AG$1:$AY$1"),0),0) -> 0 | N6: =VLOOKUP($B6,INDIRECT($D6&"!$AG$1:$AY$66"),MATCH(N$1,INDIRECT($D6&"!$AG$1:$AY$1"),0),0) -> 0 | ... V6: =VLOOKUP($B6,INDIRECT($D6&"!$AG$1:$AY$66"),MATCH(V$1,INDIRECT($D6&"!$AG$1:$AY$1"),0),0) -> 0 | W6: =VLOOKUP($B6,INDIRECT($D6&"!$AG$1:$AY$66"),MATCH(W$2,INDIRECT($D6&"!$AG$1:$AY$1"),0),0) -> 200 | X6: =IFERROR(_xlfn.XLOOKUP($B6,社保汇总表!B:B,社保汇总表!G:G),0) -> 420.68 | Y6: =VLOOKUP($B6,公积金汇总表!$P:$Q,2,0) -> 126 | AA6: =VLOOKUP($B6,INDIRECT($D6&"!$AG$1:$AY$66"),MATCH(AA$1,INDIRECT($D6&"!$AG$1:$AY$1"),0),0) -> 全勤 | AB6: =VLOOKUP($B6,INDIRECT($D6&"!$AG$1:$AZ$66"),MATCH(AB$1,INDIRECT($D6&"!$AG$1:$AZ$1"),0),0) -> 5
A7: 5 | B7: 李思思 | C7: 4 | D7: 深圳 | E7: 财务部 | F7: 46113 | G7: =VLOOKUP($B7,INDIRECT($D7&"!$AG$1:$AY$66"),MATCH(G$1,INDIRECT($D7&"!$AG$1:$AY$1"),0),0) -> 24 | H7: =VLOOKUP($B7,INDIRECT($D7&"!$AG$1:$AY$66"),MATCH(H$1,INDIRECT($D7&"!$AG$1:$AY$1"),0),0) -> 23 | I7: =VLOOKUP($B7,INDIRECT($D7&"!$AG$1:$AY$66"),MATCH(I$1,INDIRECT($D7&"!$AG$1:$AY$1"),0),0) -> 0 | J7: =VLOOKUP($B7,INDIRECT($D7&"!$AG$1:$AY$66"),MATCH(J$1,INDIRECT($D7&"!$AG$1:$AY$1"),0),0) -> 0 | K7: =VLOOKUP($B7,INDIRECT($D7&"!$AG$1:$AY$66"),MATCH(K$1,INDIRECT($D7&"!$AG$1:$AY$1"),0),0) -> 0 | L7: =VLOOKUP($B7,INDIRECT($D7&"!$AG$1:$AY$66"),MATCH(L$1,INDIRECT($D7&"!$AG$1:$AY$1"),0),0) -> 0 | M7: =VLOOKUP($B7,INDIRECT($D7&"!$AG$1:$AY$66"),MATCH(M$1,INDIRECT($D7&"!$AG$1:$AY$1"),0),0) -> 0 | N7: =VLOOKUP($B7,INDIRECT($D7&"!$AG$1:$AY$66"),MATCH(N$1,INDIRECT($D7&"!$AG$1:$AY$1"),0),0) -> 0 | ... V7: =VLOOKUP($B7,INDIRECT($D7&"!$AG$1:$AY$66"),MATCH(V$1,INDIRECT($D7&"!$AG$1:$AY$1"),0),0) -> 0 | W7: =VLOOKUP($B7,INDIRECT($D7&"!$AG$1:$AY$66"),MATCH(W$2,INDIRECT($D7&"!$AG$1:$AY$1"),0),0) -> 200 | X7: =IFERROR(_xlfn.XLOOKUP($B7,社保汇总表!B:B,社保汇总表!G:G),0) -> 420.68 | Y7: =VLOOKUP($B7,公积金汇总表!$P:$Q,2,0) -> 126 | AA7: =VLOOKUP($B7,INDIRECT($D7&"!$AG$1:$AY$66"),MATCH(AA$1,INDIRECT($D7&"!$AG$1:$AY$1"),0),0) -> 全勤，外出 6.5小时(04/22 12:00-04/22 18:30) | AB7: =VLOOKUP($B7,INDIRECT($D7&"!$AG$1:$AZ$66"),MATCH(AB$1,INDIRECT($D7&"!$AG$1:$AZ$1"),0),0) -> 2
A8: 6 | B8: 邓茗霞 | C8: 4 | D8: 深圳 | E8: 采购部 | F8: 44732 | G8: =VLOOKUP($B8,INDIRECT($D8&"!$AG$1:$AY$66"),MATCH(G$1,INDIRECT($D8&"!$AG$1:$AY$1"),0),0) -> 24 | H8: =VLOOKUP($B8,INDIRECT($D8&"!$AG$1:$AY$66"),MATCH(H$1,INDIRECT($D8&"!$AG$1:$AY$1"),0),0) -> 22 | I8: =VLOOKUP($B8,INDIRECT($D8&"!$AG$1:$AY$66"),MATCH(I$1,INDIRECT($D8&"!$AG$1:$AY$1"),0),0) -> 5 | J8: =VLOOKUP($B8,INDIRECT($D8&"!$AG$1:$AY$66"),MATCH(J$1,INDIRECT($D8&"!$AG$1:$AY$1"),0),0) -> 0 | K8: =VLOOKUP($B8,INDIRECT($D8&"!$AG$1:$AY$66"),MATCH(K$1,INDIRECT($D8&"!$AG$1:$AY$1"),0),0) -> 0 | L8: =VLOOKUP($B8,INDIRECT($D8&"!$AG$1:$AY$66"),MATCH(L$1,INDIRECT($D8&"!$AG$1:$AY$1"),0),0) -> 0.44 | M8: =VLOOKUP($B8,INDIRECT($D8&"!$AG$1:$AY$66"),MATCH(M$1,INDIRECT($D8&"!$AG$1:$AY$1"),0),0) -> 0.56 | N8: =VLOOKUP($B8,INDIRECT($D8&"!$AG$1:$AY$66"),MATCH(N$1,INDIRECT($D8&"!$AG$1:$AY$1"),0),0) -> 0 | ... V8: =VLOOKUP($B8,INDIRECT($D8&"!$AG$1:$AY$66"),MATCH(V$1,INDIRECT($D8&"!$AG$1:$AY$1"),0),0) -> 0 | W8: =VLOOKUP($B8,INDIRECT($D8&"!$AG$1:$AY$66"),MATCH(W$2,INDIRECT($D8&"!$AG$1:$AY$1"),0),0) -> 0 | X8: =IFERROR(_xlfn.XLOOKUP($B8,社保汇总表!B:B,社保汇总表!G:G),0) -> 420.68 | Y8: =VLOOKUP($B8,公积金汇总表!$P:$Q,2,0) -> 118 | AA8: =VLOOKUP($B8,INDIRECT($D8&"!$AG$1:$AY$66"),MATCH(AA$1,INDIRECT($D8&"!$AG$1:$AY$1"),0),0) -> 事假 3.5小时(04/04 09:00-04/04 12:30);年假 4.5小时(04/10 14:00-04/10 18:30)，迟到2次共5分钟 | AB8: =VLOOKUP($B8,INDIRECT($D8&"!$AG$1:$AZ$66"),MATCH(AB$1,INDIRECT($D8&"!$AG$1:$AZ$1"),0),0) -> 0
A9: 7 | B9: 张丽玲 | C9: 4 | D9: 深圳 | E9: 采购部 | F9: 44739 | G9: =VLOOKUP($B9,INDIRECT($D9&"!$AG$1:$AY$66"),MATCH(G$1,INDIRECT($D9&"!$AG$1:$AY$1"),0),0) -> 24 | H9: =VLOOKUP($B9,INDIRECT($D9&"!$AG$1:$AY$66"),MATCH(H$1,INDIRECT($D9&"!$AG$1:$AY$1"),0),0) -> 22.44 | I9: =VLOOKUP($B9,INDIRECT($D9&"!$AG$1:$AY$66"),MATCH(I$1,INDIRECT($D9&"!$AG$1:$AY$1"),0),0) -> 0 | J9: =VLOOKUP($B9,INDIRECT($D9&"!$AG$1:$AY$66"),MATCH(J$1,INDIRECT($D9&"!$AG$1:$AY$1"),0),0) -> 0 | K9: =VLOOKUP($B9,INDIRECT($D9&"!$AG$1:$AY$66"),MATCH(K$1,INDIRECT($D9&"!$AG$1:$AY$1"),0),0) -> 0 | L9: =VLOOKUP($B9,INDIRECT($D9&"!$AG$1:$AY$66"),MATCH(L$1,INDIRECT($D9&"!$AG$1:$AY$1"),0),0) -> 0.56 | M9: =VLOOKUP($B9,INDIRECT($D9&"!$AG$1:$AY$66"),MATCH(M$1,INDIRECT($D9&"!$AG$1:$AY$1"),0),0) -> 0 | N9: =VLOOKUP($B9,INDIRECT($D9&"!$AG$1:$AY$66"),MATCH(N$1,INDIRECT($D9&"!$AG$1:$AY$1"),0),0) -> 0 | ... V9: =VLOOKUP($B9,INDIRECT($D9&"!$AG$1:$AY$66"),MATCH(V$1,INDIRECT($D9&"!$AG$1:$AY$1"),0),0) -> 0 | W9: =VLOOKUP($B9,INDIRECT($D9&"!$AG$1:$AY$66"),MATCH(W$2,INDIRECT($D9&"!$AG$1:$AY$1"),0),0) -> 0 | X9: =IFERROR(_xlfn.XLOOKUP($B9,社保汇总表!B:B,社保汇总表!G:G),0) -> 420.68 | Y9: =VLOOKUP($B9,公积金汇总表!$P:$Q,2,0) -> 118 | AA9: =VLOOKUP($B9,INDIRECT($D9&"!$AG$1:$AY$66"),MATCH(AA$1,INDIRECT($D9&"!$AG$1:$AY$1"),0),0) -> 事假 4.5小时(04/04 14:00-04/04 18:30) | AB9: =VLOOKUP($B9,INDIRECT($D9&"!$AG$1:$AZ$66"),MATCH(AB$1,INDIRECT($D9&"!$AG$1:$AZ$1"),0),0) -> 1
A10: 8 | B10: 施晓珊 | C10: 4 | D10: 深圳 | E10: 采购部 | F10: 46085 | G10: =VLOOKUP($B10,INDIRECT($D10&"!$AG$1:$AY$66"),MATCH(G$1,INDIRECT($D10&"!$AG$1:$AY$1"),0),0) -> 24 | H10: =VLOOKUP($B10,INDIRECT($D10&"!$AG$1:$AY$66"),MATCH(H$1,INDIRECT($D10&"!$AG$1:$AY$1"),0),0) -> 23 | I10: =VLOOKUP($B10,INDIRECT($D10&"!$AG$1:$AY$66"),MATCH(I$1,INDIRECT($D10&"!$AG$1:$AY$1"),0),0) -> 0 | J10: =VLOOKUP($B10,INDIRECT($D10&"!$AG$1:$AY$66"),MATCH(J$1,INDIRECT($D10&"!$AG$1:$AY$1"),0),0) -> 0 | K10: =VLOOKUP($B10,INDIRECT($D10&"!$AG$1:$AY$66"),MATCH(K$1,INDIRECT($D10&"!$AG$1:$AY$1"),0),0) -> 0 | L10: =VLOOKUP($B10,INDIRECT($D10&"!$AG$1:$AY$66"),MATCH(L$1,INDIRECT($D10&"!$AG$1:$AY$1"),0),0) -> 0 | M10: =VLOOKUP($B10,INDIRECT($D10&"!$AG$1:$AY$66"),MATCH(M$1,INDIRECT($D10&"!$AG$1:$AY$1"),0),0) -> 0 | N10: =VLOOKUP($B10,INDIRECT($D10&"!$AG$1:$AY$66"),MATCH(N$1,INDIRECT($D10&"!$AG$1:$AY$1"),0),0) -> 0 | ... V10: =VLOOKUP($B10,INDIRECT($D10&"!$AG$1:$AY$66"),MATCH(V$1,INDIRECT($D10&"!$AG$1:$AY$1"),0),0) -> 0 | W10: =VLOOKUP($B10,INDIRECT($D10&"!$AG$1:$AY$66"),MATCH(W$2,INDIRECT($D10&"!$AG$1:$AY$1"),0),0) -> 200 | X10: =IFERROR(_xlfn.XLOOKUP($B10,社保汇总表!B:B,社保汇总表!G:G),0) -> 420.68 | Y10: =VLOOKUP($B10,公积金汇总表!$P:$Q,2,0) -> 126 | AA10: =VLOOKUP($B10,INDIRECT($D10&"!$AG$1:$AY$66"),MATCH(AA$1,INDIRECT($D10&"!$AG$1:$AY$1"),0),0) -> 全勤 | AB10: =VLOOKUP($B10,INDIRECT($D10&"!$AG$1:$AZ$66"),MATCH(AB$1,INDIRECT($D10&"!$AG$1:$AZ$1"),0),0) -> 0
